Workbook

Sheet 概要・活用ガイド
A1: 技術士一次試験 衛生工学部門 過去問統合データベース (H23〜R7)
A2: 平成23年度〜令和7年度 (全16回・560問題) / 全問の問題文・選択肢・公式正答を収録したスプレッドシート（v28：問題文・分類の訂正版（区分を15に集約））
A4: 収録試験回数 | C4: 総収録問題数 | E4: 問題文・選択肢の収録範囲 | G4: 3ブロック分類
A5: 16 回分 | C5: 560 問 | E5: 全16回(560問) | G5: 100 %
A6: H23〜R7 (R1本・再含む) | C6: 35問 × 16回 | E6: 問題文・全選択肢付き | G6: 大分類・区分（15区分）＋出題論点（細目）完備
A8: ■ ワークブックの構成と活用方法
A9: シート名 | B9: 内容と目的 | C9: おすすめの活用方法
A10: 概要・活用ガイド | B10: 本データベースの概要、収録範囲、凡例の解説 | C10: 全体の構成把握、学習計画の立案
A11: 各年度シート（R7〜H23） | B11: 各年度の全35問の問題文全文、選択肢①〜⑤、公式正答、分類（R1は本試験・再試験の2シート） | C11: 年度別の本番形式演習、年度単位のチェック
A12: 過去問マスターDB | B12: H23〜R7全560問のテーマ、正答、分類、問題文・選択肢のマスターリスト | C12: オートフィルターによる頻出テーマ・苦手ジャンルの絞り込み
A13: ジャンル別出題傾向 | B13: 15区分別の出題状況（問題数・出題回数・平均問題数は自動集計）と学習優先度（S/A/B） | C13: 出題確率の高い「Sランク分野」からの効率的学習
A14: 正答一覧マトリクス | B14: 問1〜問35 × 16回分の正答番号クロス一覧表 | C14: 自己採点、正答番号の横断確認
A15: 修正履歴 | B15: v15からv28への修正内容（修正前後・根拠） | C15: 修正箇所の確認、今後の更新時の参照

Sheet 図表
A1: 図・表が必要な問題の原本画像（技術士第一次試験 過去問PDFより切り出し）
A3: 問題ID | B3: 内容 | C3: 区分 | D3: 問題文（DB） | E3: 図表
A4: H23-01 | B4: 床断面の熱橋（層構成 d₁・d₂・d₃） | C4: A | D4: 下図に示す外気に接する床断面の熱橋を考慮した熱貫流率の計算方法について，最も適切なものはどれか。ただし，熱伝導率をλ，厚さをdとし，木根太によって生じる熱橋の面積比率（熱橋面積率）を A_HB，室内側熱伝達抵抗を R_i，外気側熱伝達抵抗を R_o とする。また，木根太の厚さ d_3 は，断熱材の厚さ d_2 よりも大きいものとする。
A5: H23-08 | B5: 空調系統図と空気線図 | C5: A | D5: 下図に示すように，外気冷却コイルで室内空気の湿度を満足させるまで冷却し，還気（加熱又は冷却）コイルで室内温度を満足するように制御して，極力再熱負荷を発生させない空調システムを採用した。室内負荷として最も近い値はどれか。ただし，与条件は以下のとおりとする。 空気の比容積：0.83 m³／kg(DA) 空調吹出し風量：30,000 m³／h 外気風量：10,000 m³／h 空調系統：空調系統図参照 空気線図上のポイント：空調系統図参照 システム内発熱（送風機，ダクト断熱）：無視
A6: H24-03 | B6: 図A・図B（開口の位置） | C6: A | D6: 図Aに示す建物の換気量をQとするとき，図Bに示す建物の換気量に最も近いものはどれか。ただし，図A，図Bともに室温は20℃で，建物外部は無風，開口部の流量係数は全て等しいとする。図は，それぞれ建物の鉛直断面を示したものである。
A7: H24-06 | B7: 2層壁体の厚さ | C7: A | D7: 下図に示す2層からなる壁体の熱通過率（熱貫流率）として，最も近い値はどれか。ただし，α_o ＝ 20 W/(m²・K)，α_i ＝ 8 W/(m²・K)，λ_1 ＝ 1.5 W/(m・K)，λ_2 ＝ 0.02 W/(m・K) とする。
A8: H24-09 | B8: ダクト合流部・与条件・局部抵抗係数表 | C8: A | D8: 下図に示す長方形ダクトの合流部（Ⓐ → Ⓑ）の局部圧力損失として，最も近い値はどれか。ただし，与条件は以下の通りとする。
A9: H25-04 | B9: 開口の直列合成 | C9: B | D9: 二面開口住戸の通風性能について，風上開口の相当（有効）開口面積α1A1，風下開口の相当（有効）開口面積α2A2が下図に示す値である場合，それらの直列合成による相当（有効）開口面積（合成αA）の値に最も近いものはどれか。［図：α1A1＝10.0 m²，α2A2＝5.0 m²］
A10: H25-07 | B10: p-h線図と選択肢表 | C10: B | D10: 次の記述の，［ ］に入る記号又は数式の組合せとして最も適切なものはどれか。 下図に示す圧縮式冷凍機の冷凍サイクルにおいて，［A］は圧縮過程を，［B］は蒸発過程をそれぞれ示しており，この冷凍サイクルの成績係数は，［C］で表される。［図：p-h線図。1→2は蒸発，2→3は圧縮，3→4は凝縮，4→1は膨張。エンタルピーはh1，h2，h3］
A11: H26-01 | B11: 点光源（180cd・高さ3m・30°） | C11: B | D11: 下図に示す点光源に照らされたA点の水平面照度に最も近い値はどれか。ただし，点光源の配光特性は一様なものとし，反射は考慮しないものとする。［図：点光源の光度180cd，床面からの高さ3m，A点は点光源から見て水平面に対し30°の位置］
A12: H26-09 | B12: 空調系統図と空気線図 | C12: A | D12: 下図に示すように，外気冷却コイルで室内空気の湿度を満足させるまで冷却し，還気（加熱又は冷却）コイルで室内温度を満足するように制御して，極力再熱負荷を発生させない空調システムを採用し，さらにCO2制御による外気量制御を採用して省エネルギーを図っている。空気線図上に示す運転状態における室内負荷に最も近い値はどれか。ただし，与条件は以下のとおりとする。 空気の比容積：0.83 m³／kg(DA) 空調吹出し風量：20,000 m³／h 外気風量：4,000 m³／h（定格外気風量：6,000 m³／h，CO2制御） 空調系統：空調系統図参照 空気線図上のポイント：空調系統図参照 システム内発熱（送風
A13: H26-23 | B13: 浄化槽フローシートと断面図 | C13: A | D13: 下図に示す嫌気ろ床接触ばっ気方式の小型浄化槽に関する次の記述のうち，最も不適切なものはどれか。
A14: H27-14 | B14: 全圧・静圧分布図（a〜d） | C14: A | D14: 下図は，送風機の吹出し側，吸込み側に，それぞれ円形ダクトを取り付け，送風機を運転している状況におけるダクトの全圧，静圧の分布を示したものである。送風機全圧を図中の矢印で示すa, b, c, dの圧力を用いて表すとすれば，最も適切なものは次のうちどれか。ただし，a, b, c, dの値は絶対値である。
A15: H27-17 | B15: 二面開口住戸（風速・風圧係数） | C15: A | D15: 下図に示す二面開口住戸の風力換気量に最も近い値はどれか。ただし，外部風速（v），各開口部の風圧係数（C），実効面積（αA）は下図に示す値とする。
... A31: R7-02 | B31: 点光源（1000cd・2m・60°） | C31: B | D31: 下図に示す点光源に照らされたＡ点の水平面照度に最も近い値はどれか。ただし，点光源の配光特性は一様なものとし，反射は考慮しないものとする。[点光源(光度1000cd)、高さ2m、照射角60°、A点]

Sheet R7(令和7年度)問題・選択肢
A1: 問題ID | B1: 設問番号 | C1: 大分類(ブロック) | D1: サブジャンル | E1: 公式正答 | F1: 問題のテーマ・内容概要 | G1: 問題文 | H1: 選択肢① | I1: 選択肢② | J1: 選択肢③ | K1: 選択肢④ | L1: 選択肢⑤ | M1: 出題論点（細目）
A2: R7-01 | B2: Ⅲ-1 | C2: 建築環境・設備・建築物衛生管理 | D2: 光・音 | E2: 3 | F2: 垂直ルーバー、太陽放射スペクトル、天空日射と直達日射、南向き外壁日射量、外壁色と日射熱取得 | G2: 日照・日射に関する次の記述のうち，最も不適切なものはどれか。 | H2: ① 垂直ルーバーや縦型ブラインドは角度調整を行わない場合は，建物の東西面などほぼ正面からの日射を遮へいできない。 | I2: ② 大気圏外の太陽放射は，地表面を覆っている大気によって散乱・吸収され，およそ 0.3～2.5μm の範囲のみが地表面に到達する。 | J2: ③ 天空日射の光源は日射の大気による散乱であるため，大気透過率が大きいほど天空日射量は大きくなり，直達日射量は小さくなる。 | K2: ④ 夏至の南向きの外壁の鉛直面は，東西を向いた外壁の鉛直面よりも入射する直達日射量は少ない。 | L2: ⑤ 白やオフホワイトなどの明るい色の外壁は日射吸収率が小さいため，黒色や暗褐色の外壁に比べて壁が吸収する日射熱取得を削減することができる。 | M2: 日照・日射・採光
A3: R7-02 | B3: Ⅲ-2 | C3: 建築環境・設備・建築物衛生管理 | D3: 光・音 | E3: 5 | F3: 点光源（光度1000cd、高さ2m、照射角60°）からのA点における水平面照度の計算 | G3: 下図に示す点光源に照らされたＡ点の水平面照度に最も近い値はどれか。ただし，点光源の配光特性は一様なものとし，反射は考慮しないものとする。[点光源(光度1000cd)、高さ2m、照射角60°、A点] | H3: ① 250 lx | I3: ② 63 lx | J3: ③ 54 lx | K3: ④ 42 lx | L3: ⑤ 31 lx | M3: 照明・光環境
A4: R7-03 | B4: Ⅲ-3 | C4: 建築環境・設備・建築物衛生管理 | D4: 熱・湿気 | E4: 4 | F4: 自然対流熱伝達率（暖房・冷房）、熱伝導率の温度依存性、ニュートンの冷却則、木材と土・しっくいの熱伝導率比較、空気層の熱抵抗 | G4: 伝熱に関する次の記述のうち，最も不適切なものはどれか。 | H4: ① 自然対流熱伝達率は，暖房時の天井面よりも，冷房時の天井面の方が低い値となる。 | I4: ② 熱伝導率の値は温度が上昇するとやや変化するが，建築分野では定数として扱って良い。 | J4: ③ 壁体のような固体表面から空気へ熱が伝えられることを対流熱伝達といい，その伝熱量はニュートンの冷却則で与えられる。 | K4: ④ 木材の熱伝導率は，土やしっくいの熱伝導率よりも大きい。 | L4: ⑤ 壁体内や二重ガラスの空気層の熱抵抗は，空気層の厚さが増すと増大するが，厚さが10cmを超えるとその値はほとんど増えない。 | M4: 伝熱・断熱
A5: R7-04 | B5: Ⅲ-4 | C5: 建築環境・設備・建築物衛生管理 | D5: 光・音 | E5: 2 | F5: コインシデンス効果と壁厚、複層ガラスと一重ガラスの遮音性能比較、二重壁の低音域共鳴透過、板振動型吸音、多孔質型吸音 | G5: 各種材料の遮音性能に関する次の記述のうち，最も不適切なものはどれか。 | H5: ① 壁に音が斜め入射する場合，壁の屈曲波の周波数と一致すると，壁が大きく振動して音が透過する。これをコインシデンス効果といい，壁厚が厚い場合は，その効果の対象となる周波数が中低音域まで下がるので，対策を要する場合がある。 | I5: ② ガラスの厚さを合計して6mmとし，面密度を一定とした場合，複層ガラス窓は同一面密度の一重ガラス窓と比べて遮音性能は高い。 | J5: ③ 二重壁では，低周波部分で透過損失の著しい落ち込みが見られ，この現象を低音域共鳴透過と呼ぶ。 | K5: ④ 板振動型吸音機構では，低音域の共振周波数付近で吸音率は高く，中高音域の吸音率は小さい。 | L5: ⑤ 多孔質型吸音機構では，波長の長い低音に対して吸音率を高めるためには，材料を厚くするか剛壁から離して設置する必要がある。 | M5: 音環境
A6: R7-05 | B6: Ⅲ-5 | C6: 建築環境・設備・建築物衛生管理 | D6: 熱・湿気 | E6: 2 | F6: 北側居室・押入の表面結露、壁体内の防湿層配置（高温・室内側）、通気層の設置、夏型結露、冬季表面結露防止対策 | G6: 建物の結露に関する次の記述のうち，最も不適切なものはどれか。 | H6: ① 家族が集う南側居室から暖房を行っていない北側居室へ水蒸気が拡散した場合，温度が低い外壁内表面や空気流動が少ない押入の中等に結露が生じる恐れが多い。 | I6: ② 内部結露の防止には，壁体内に水蒸気が侵入しないようにすることが第一であり，壁体内に防湿層を入れる場合，温度の高い断熱材の室外側に配置しなければならない。 | J6: ③ 内部結露の防止には，壁体内部の水蒸気を外気に逃がすための通気層を断熱層室外側に設ける構法を採用すると良い。 | K6: ④ 夏型結露とは，高温多湿の空気が低温度の空間に流れ込んで，相対湿度を上昇させることにより，発生する結露である。 | L6: ⑤ 冬季の表面結露の防止には，「室内における水蒸気発生の抑制」，「換気による室内絶対湿度の低下」，「外壁断熱強化による室内側表面温度の上昇」などが考えられる。 | M6: 結露・湿気・湿り空気
A7: R7-06 | B7: Ⅲ-6 | C7: 建築環境・設備・建築物衛生管理 | D7: 光・音 | E7: 1 | F7: 赤外放射の波長定義（780nm以上）、雲と実効放射量、単層壁の熱貫流メカニズム、ステファン・ボルツマンの法則、建材表面の放射率 | G7: 日射・熱移動に関する次の記述のうち，最も不適切なものはどれか。 | H7: ① 波長380nm以下の範囲を赤外放射と呼ぶ。 | I7: ② 実効放射量（夜間放射量）は，雲があるときは，雲がないときに比較して減少する。 | J7: ③ 単層壁の熱貫流は，壁体内部では熱伝導，壁の表面では対流及び放射によって行われている。 | K7: ④ 完全黒体から放出される放射エネルギーは，絶対温度の4乗に比例する。 | L7: ⑤ 多くの建材（灰色体）の表面の放射率は0.9前後を示し，入射する放射エネルギーの9割前後を吸収する。 | M7: 日照・日射・採光
A8: R7-07 | B8: Ⅲ-7 | C8: 建築環境・設備・建築物衛生管理 | D8: 熱・湿気 | E8: 3 | F8: 相当隙間面積値（C値）、外付け・内付けブラインドの日射遮蔽係数SC、コンクリート外断熱・内断熱の熱応答性、コアンダ効果（壁面付着噴流）、通風開口面積比 | G8: 熱環境に関する次の記述のうち，最も不適切なものはどれか。 | H8: ① 総相当隙間面積［cm²］を，外皮内の実質延べ床面積［m²］で除したものを相当隙間面積値（C値）という。 | I8: ② 開口部の日射遮蔽装置として，内付けブラインドを設置するよりも外付けブラインドを設置する方が日射遮蔽係数SCは，小さくなる。 | J8: ③ コンクリート構造の躯体では，外断熱工法の方が内断熱工法よりも熱容量の小さい材料で室内空間が覆われるため，空調や日射受熱による室温の応答性が良い。 | K8: ④ 壁面や天井面に近接した噴流はその面に付着して流れ，自由噴流に比べ流速が減衰しにくく，到達距離が長い傾向にある。 | L8: ⑤ 通風により室内に適当な気流速度を得るためには，風上側の開口を小さめに，風下側の開口を大きめに設定することも重要である。 | M8: 伝熱・断熱
A9: R7-08 | B9: Ⅲ-8 | C9: 建築環境・設備・建築物衛生管理 | D9: 空調 | E9: 2 | F9: 湿り空気の比エンタルピー状態変化計算（乾き空気1000kgの加熱・加湿に必要な熱量MJ） | G9: 湿り空気の比エンタルピーh ［kJ/kg(DA)］は次の式で表せる。 h = 1.0 t + (2500 + 1.8 t) x ［kJ/kg(DA)］ ただし，t：乾球温度［℃］，x：絶対湿度［kg/kg(DA)］。乾き空気1000kg(DA)を含む，乾球温度10℃，絶対湿度0.004 kg/kg(DA)の湿り空気を，蒸気で加熱・加湿し，乾球温度42℃，絶対湿度0.014 kg/kg(DA)としたときの空気の得た熱量の値として，最も適切なものはどれか。 | H9: ① 58 kJ | I9: ② 58 MJ | J9: ③ 78 MJ | K9: ④ 32 MJ | L9: ⑤ 20 kJ | M9: 空調計算（負荷・空気線図・冷凍サイクル）
A10: R7-09 | B10: Ⅲ-9 | C10: 建築環境・設備・建築物衛生管理 | D10: 換気・室内空気 | E10: 4 | F10: 顕熱発熱量（6480W）と室内外温度差（34℃-19℃=15K）からの必要換気量計算（m³/h） | G10: 室内機器の顕熱発熱量が6480 Wのときに，室温を34 ℃に保つための換気量に最も近い値はどれか。ただし，外気温19 ℃，空気密度1.2 kg/m³，乾き空気の定圧比熱は1.0 kJ/(kg・K)とする。 | H10: ① 100 m³/h | I10: ② 360 m³/h | J10: ③ 1023 m³/h | K10: ④ 1296 m³/h | L10: ⑤ 1555 m³/h | M10: 換気・通風
A11: R7-10 | B11: Ⅲ-10 | C11: 建築環境・設備・建築物衛生管理 | D11: 空調 | E11: 3 | F11: パーソナル空調のフレキシビリティ、執務者快適性、タスク・アンビエント空調の制御概念、中央方式空調における個人対応、エネルギー消費制御 | G11: パーソナル空調に関する次の記述のうち，最も不適切なものはどれか。 | H11: ① 什器のレイアウト変更やOA機器の増設など，容易に対処できるフレキシビリティも備えるべき条件である。 | I11: ② 省エネルギー性のほかに，導入で期待される効果として，執務者の快適性の向上があげられる。 | J11: ③ タスク域は緩和した設定で空調を行い，在席時にアンビエント域を通常の空調とすることで，空間全体の空調エネルギーを抑えることが可能になる。 | K11: ④ 従来の中央方式空調システムでも吹出し口の配置・形状などによって，個人ごとの対応が可能である。 | L11: ⑤ 運転方法や制御方法が悪いと，逆にエネルギーを浪費する可能性がある。 | M11: 空調方式・省エネルギー
A12: R7-11 | B12: Ⅲ-11 | C12: 建築環境・設備・建築物衛生管理 | D12: 空調 | E12: 2 | F12: コジェネ部分負荷特性、BEMSとコミッショニング、エアフローウィンドウの目的、全熱交換器と外気冷房、CO2濃度による外気量制御 | G12: 省エネルギーシステムに関する次の記述のうち，最も適切なものはどれか。 | H12: ① コージェネレーション方式では，建物内の電気や熱負荷など，負荷率が下がると発電効率は上昇する。 | I12: ② BEMSは，性能検証（コミッショニング）を助ける手段の1つである。 | J12: ③ エアフローウィンドウ方式は，外壁を二重にしたペリメータ空調を省略する方式である。 | K12: ④ 全熱交換器を用いて換気を行う場合，中間期の外気冷房可能な時期でも，省エネルギー効果が期待できる。 | L12: ⑤ 事務所の場合，給気のCO2濃度をもとに取入れ外気量を制御することで外気負荷の軽減が図れる。 | M12: 空調方式・省エネルギー
A13: R7-12 | B13: Ⅲ-12 | C13: 建築環境・設備・建築物衛生管理 | D13: 給排水・防災 | E13: 2 | F13: 一般給水圧力上限（300〜400kPa）、高置水槽容量と揚水ポンプの相互関係、受水槽有効容量（日予想給水量の1/2程度）、受水槽周囲点検スペース（600mm/1000mm）、クロスコネクションの定義 | G13: 給水設備に関する次の記述のうち，最も適切なものはどれか。 | H13: ① 一般に給水管の給水圧力の上限値は，ホテルやアパートなど人間生活の場においては，400〜500kPa程度として計画する。 | I13: ② 高置水槽方式においては，高置水槽の容量と揚水ポンプの揚水量とは相互に関係を有する。 | J13: ③ 受水槽の有効容量は，水道本管の水圧により引込み水量が変化することと，水道本管の断水なども考慮して，一般に1日予想給水量の60〜80％程度としている。 | K13: ④ 受水槽周囲には，点検スペースとして，300mm以上，上部には600mm以上の空間を設ける。 | L13: ⑤ クロスコネクションとは，水受け容器中に吐き出された水，又はその他の溶液が給水管内に生じた負圧による吸引作用のため，給水管内に逆流することをいう。 | M13: 給水・給湯
... A36: R7-35 | B36: Ⅲ-35 | C36: 廃棄物管理 | D36: 法制度・リサイクル・循環型社会 | E36: 5 | F36: 生活環境影響調査指針（許可要施設での実施義務、地域・構造特性による非該当項目の割愛可能、変更許可時も必要、集合設置時は一括での実施が可能） | G36: 「廃棄物処理施設生活環境影響調査指針（平成18年9月環境省）」に関する次の記述のうち，最も不適切なものはどれか。 | H36: ① 生活環境影響調査は，許可を要するすべての廃棄物処理施設について実施が義務づけられている。 | I36: ② 生活環境影響調査の対象とする調査事項は，廃棄物処理施設の稼働等に伴って生じる生活環境への影響に関するもので，大気質，騒音，振動，悪臭，水質及び地下水である。 | J36: ③ 対象施設の構造上の特性や地域特性からみて，影響が発生することが想定されない調査事項（例えば，排水を排出しない施設の場合の水質汚濁など）については，具体的な調査を実施する必要がない。 | K36: ④ 生活環境影響調査は，廃棄物処理施設の変更の許可を受ける場合にも必要である。 | L36: ⑤ 複数の廃棄物処理施設を集合して設置する場合は，それぞれの施設ごとに生活環境影響調査を実施しなければならない。 | M36: 廃棄物処理法・制度・処理施設・その他

Sheet R6(令和6年度)問題・選択肢
A1: 問題ID | B1: 設問番号 | C1: 大分類(ブロック) | D1: サブジャンル | E1: 公式正答 | F1: 問題のテーマ・内容概要 | G1: 問題文 | H1: 選択肢① | I1: 選択肢② | J1: 選択肢③ | K1: 選択肢④ | L1: 選択肢⑤ | M1: 出題論点（細目）
A2: R6-01 | B2: Ⅲ-1 | C2: 建築環境・設備・建築物衛生管理 | D2: 光・音 | E2: 4 | F2: 室の容積・吸音率変化に伴う残響時間の計算 | G2: 間口5m、奥行き5m、天井高さ3m、吸音率0.1の内装で作られた直方体の室がある。この室の残響時間は1.1秒であった。次に、内装のうち壁のみを吸音率0.25の材料に変更した。変更後の室の残響時間として、最も近い値はどれか。 | H2: ① 3.8秒 | I2: ② 2.4秒 | J2: ③ 0.8秒 | K2: ④ 0.6秒 | L2: ⑤ 0.4秒 | M2: 音環境
A3: R6-02 | B3: Ⅲ-2 | C3: 建築環境・設備・建築物衛生管理 | D3: 熱・湿気 | E3: 3 | F3: 湿気環境、水蒸気発生量、二重サッシおよび乾湿球湿度計に関する記述 | G3: 湿気環境に関する次の記述のうち、最も不適切なものはどれか。 | H3: ① 木材の含水率が20%を超えると腐朽菌が繁殖しやすくなるため、住宅の土台回りは高含水率になりやすいので、床下換気を十分にする必要がある。 | I3: ② 環境温度20℃において、静座時に人体（成人男性）から放出される水蒸気量は、34g/(h・人)程度である。 | J3: ③ 結露を防ぐために二重サッシを使用する場合、外気側のサッシはできるだけ気密にし、室内側は湿気が逃げやすい構造にする必要がある。 | K3: ④ 温度25℃、相対湿度95%が最もカビが発生しやすい条件であるといわれている。 | L3: ⑤ アスマン通風乾湿計において、乾球及び湿球の周辺空気が飽和している状態では、乾球温度と湿球温度の示度は等しくなる。 | M3: 結露・湿気・湿り空気
A4: R6-03 | B4: Ⅲ-3 | C4: 建築環境・設備・建築物衛生管理 | D4: 温熱・省エネ指標 | E4: 5 | F4: 作用温度(OT)、熱中性域、アダプティブモデル、PMVおよびSET*の定義 | G4: 温熱快適性に関する次の記述のうち、最も不適切なものはどれか。 | H4: ① 作用温度（OT）は、静穏な環境では気温と平均放射温度の平均値とみなせる。 | I4: ② 生理的に快適な条件は、体温調節機構が無意識に最小限の努力で血管の収縮、拡張を行い、皮膚表面温度を約33℃に保てる熱中性域と呼ばれる状態にあることである。 | J4: ③ 環境適応モデル（アダプティブモデル）は、中央制御方式の空調を行う建物と、在室者自らが窓の開閉可能な自然換気方式の建物とでは、在室者の快適性が異なることを示したものである。 | K4: ④ ドラフトを防ぐため、作用温度（OT）が22.5℃以下の場合で、予想平均温冷感申告（PMV）が±0.5の範囲では、建物や窓、空調システムに起因する気流は体周囲のどの高さにおいても0.15m/sを超えないことが望ましいとされる。 | L4: ⑤ 新有効温度（ET*）はGaggeらによる理論から導かれた体感温度で、椅座静位、着衣量1.0clo、静穏気流、平均放射温度＝空気温度という標準状態でのET*が標準新有効温度（SET*）とされる。 | M4: 温熱環境・温熱指標
A5: R6-04 | B5: Ⅲ-4 | C5: 建築環境・設備・建築物衛生管理 | D5: 熱・湿気 | E5: 2 | F5: 対流・放射熱伝達、総合熱貫流率、日射熱流および貫流熱抵抗に関する記述 | G5: 熱環境に関する次の記述のうち、最も不適切なものはどれか。 | H5: ① 壁や窓の固体表面からは対流と放射で熱が移動するが、室内側の設計用の熱伝達率は自然対流熱伝達率に放射熱伝達率を加えた9W/(m²・K)が一般に用いられる。 | I5: ② 建物全体の熱損失は、総合熱貫流率に内外の温度差を乗じて求められるが、総合熱貫流率には換気熱損失の影響は考慮されていない。 | J5: ③ 日射が当たる外壁表面から流入する熱流は、相当外気温度と外壁表面温度の差に、屋外側熱伝達率を乗じることで求められるが、建物外壁表面に日射を反射する塗料を用いると相当外気温が下がるため、室内への貫流熱流を小さく抑えることができる。 | K5: ④ 壁の熱貫流抵抗は、壁を構成する各要素の熱抵抗の和に室内側熱伝達抵抗と屋外側熱伝達抵抗を加えた値で求められる。 | L5: ⑤ 外気温度の変化が無視できる状態で、暖房運転開始・停止を同じ条件で行ったとき、断熱性の高い建物の方が低い建物より定常状態の室温は高くなり、熱容量の大きい建物は定常状態に達するまでの温度変化が緩慢になる。 | M5: 伝熱・断熱
A6: R6-05 | B6: Ⅲ-5 | C6: 建築環境・設備・建築物衛生管理 | D6: 換気・室内空気 | E6: 1 | F6: 風圧係数、圧力差、中性帯および流量係数に関する自然換気の基本法則 | G6: 建物の自然換気に関する次の記述のうち、最も不適切なものはどれか。 | H6: ① 2つの開口部があるとき、2つの開口部とも負の風圧係数となる場合、それらの風圧係数に差があっても風力換気は生じない。 | I6: ② 窓を開放した場合などの開口部通過風量は、開口部面積に比例し、圧力差の平方根に比例する。 | J6: ③ 中性帯の位置は、定性的には開口部の大きい方に近づく。 | K6: ④ 高さの異なる2つの開口部があるときの温度差換気量は、直列合成した実効面積αAに比例するとともに、室内外温度差及び開口高さの差の平方根に比例して増加する。 | L6: ⑤ 実効面積αAにおけるαは流量係数であり、開口の形状や寸法で異なるが、通常端部が直角に整形された窓では0.6〜0.7程度となる。 | M6: 換気・通風
A7: R6-06 | B7: Ⅲ-6 | C7: 建築環境・設備・建築物衛生管理 | D7: 光・音 | E7: 3 | F7: 明視の4条件、フリッカー、正反射光・直接グレアおよび設計用全天空照度 | G7: 光環境・視環境に関する次の記述のうち、最も不適切なものはどれか。 | H7: ① 明視の4条件として、対象物の明るさ、視対象と背景の対比、対象物の大きさ、見る時間が挙げられるが、このうち照明が関わるものは「対象物の明るさ」である。 | I7: ② フリッカーは不快感を引き起こす要因となるが、人間は10Hzの光の点滅に対して最も反応し、60〜70Hzで感じなくなるとされる。 | J7: ③ 視対象が高輝度ではなくても表面が光沢面で、視線と光源の位置によっては正反射した光によって視対象が見えにくくなる場合があり、これを直接グレアという。 | K7: ④ 昼光照明においては、最低照度の確保のために、設計用全天空照度として「暗い日」に当たる5000lxを用いるのが一般的である。 | L7: ⑤ 昼光照明の計算で用いる昼光率には直射日光が考慮されていないが、近年、光ダクトなど直射日光を活用する昼光利用システムがみられるようになっている。 | M7: 日照・日射・採光
A8: R6-07 | B8: Ⅲ-7 | C8: 建築環境・設備・建築物衛生管理 | D8: 空調 | E8: 5 | F8: 回転型・静止型全熱交換器の特徴および外気取入系統の計画 | G8: 全熱交換器に関する次の記述のうち、最も不適切なものはどれか。 | H8: ① 回転型は、ロータの回転に伴って排気の一部が給気側に移行することがある。 | I8: ② 静止型の給排気を隔てる仕切り板は、伝熱性と透湿性を持つ材料である。 | J8: ③ 静止型は、回転型よりも目詰まりを起こしやすい。 | K8: ④ 中間期の運転には注意が必要な場合もある。 | L8: ⑤ 空調システムに全熱交換器を使用する場合、別に外気取入用系統が必要である。 | M8: 空調方式・省エネルギー
A9: R6-08 | B9: Ⅲ-8 | C9: 建築環境・設備・建築物衛生管理 | D9: 給排水・防災 | E9: 2 | F9: シャワー給湯時の給湯量（混合湯量）計算 | G9: シャワーヘッドから給湯量（混合湯量）16L/min、使用温度（混合湯温度）40℃のお湯を出す場合、給湯温度を60℃、給水温度を15℃とすると、給湯すべき給湯量として、最も近い値はどれか。ただし、配管などの熱損失はないものとする。 | H9: ① 8.2 L/min | I9: ② 8.9 L/min | J9: ③ 10.0 L/min | K9: ④ 10.7 L/min | L9: ⑤ 11.6 L/min | M9: 給水・給湯
A10: R6-09 | B10: Ⅲ-9 | C10: 建築環境・設備・建築物衛生管理 | D10: 給排水・防災 | E10: 3 | F10: 防火ダンパのヒューズ溶融温度および鋼板厚さの規格値の組合せ | G10: 防火ダンパに関する次の記述の、[ ア ]〜[ ウ ]に入る語句の組合せとして、最も適切なものはどれか。 「ダクトに設置される防火ダンパの温度ヒューズ型の溶融温度は、一般換気用 [ ア ] 程度、排煙用 [ イ ] 程度であり、羽根及びケーシングは [ ウ ] 以上の鋼板でつくる。」 | H10: ① ア: 72℃, イ: 270℃, ウ: 1.2mm | I10: ② ア: 72℃, イ: 280℃, ウ: 1.2mm | J10: ③ ア: 72℃, イ: 280℃, ウ: 1.5mm | K10: ④ ア: 120℃, イ: 270℃, ウ: 1.5mm | L10: ⑤ ア: 120℃, イ: 280℃, ウ: 1.5mm | M10: 防災・排煙・消火
A11: R6-10 | B11: Ⅲ-10 | C11: 建築環境・設備・建築物衛生管理 | D11: 給排水・防災 | E11: 4 | F11: スイベルジョイント、ベローズ型継手、循環ポンプおよびガス給湯器能力表示 | G11: 給湯設備に関する次の記述のうち、最も不適切なものはどれか。 | H11: ① スイベルジョイント工法とは、配管の分岐部に複数のエルボを組合せて用い、可とう性を持たせた配管工法である。 | I11: ② ベローズ型伸縮継手とは、波形状に加工した管が軸方向に伸縮する構造の継手である。 | J11: ③ 強制循環方式における循環ポンプは、一般に貯湯槽の直前の返湯管部分に設置する。 | K11: ④ 給湯栓を開いて即座に湯が必要になるホテルなどでは、湯を供給する往管だけが設置された単管式が多く用いられる。 | L11: ⑤ ガス給湯器では能力表示に「号」を用いるが、1号は流量1 [L/min] の水の温度を25℃上昇させる能力である。 | M11: 給水・給湯
A12: R6-11 | B12: Ⅲ-11 | C12: 建築環境・設備・建築物衛生管理 | D12: 空調 | E12: 1 | F12: デシカント空調、エアフローウィンドウ、氷蓄熱およびパッケージ型空調の特性 | G12: 空気調和設備に関する次の記述のうち、最も不適切なものはどれか。 | H12: ① デシカント空調における除湿は、空気を冷却することで、水を凝縮して分離している。 | I12: ② エアフローウィンドウは、従来のファンコイルユニット方式と異なり、水損リスクを減らし、保守管理の省力化が可能となる。 | J12: ③ 熱源によって生成された冷温熱を蓄える蓄熱槽のうち、氷蓄熱では、同じ熱量なら水蓄熱より容積が小さくてすむ。 | K12: ④ スクリュー式冷凍機は、中規模の建物用空調及び産業用に用いられる。 | L12: ⑤ パッケージ型空調機方式では、特殊なユニットを除き、通常は外気処理機能を持たないため、室内空気質確保のための対策が必要である。 | M12: 空調方式・省エネルギー
A13: R6-12 | B13: Ⅲ-12 | C13: 建築環境・設備・建築物衛生管理 | D13: 空調 | E13: 1 | F13: 吸収式、冷却式、吸着式および圧縮式除湿装置の作動原理と用途比較 | G13: 除湿装置に関する次の記述のうち、最も不適切なものはどれか。 | H13: ① 吸収式除湿装置は、家庭用途向けであり、幅広く使用されている。 | I13: ② 冷却式除湿装置は、処理空気の温度低下と相対湿度の上昇を伴うため、これらが問題となる場合は、冷却除去後の空気を加熱（再熱）する必要がある。 | J13: ③ 吸着式除湿装置は、水分を吸着する性質を持つシリカゲル、活性アルミナ、合成ゼオライト、活性炭などの吸着剤を利用したものである。 | K13: ④ 圧縮式除湿装置は、空気を圧縮することによって水蒸気の分圧を増加させ、水蒸気の飽和点を超えさせて凝縮分離する方式であり、設備費及び運転費が高くなる。 | L13: ⑤ 冷却式除湿装置は、機構が簡単で、設備費が安く、空気の露点温度が高い場合に有利である。 | M13: 空調機器・ダクト・熱源
... A36: R6-35 | B36: Ⅲ-35 | C36: 廃棄物管理 | D36: 最終処分場・浸出水 | E36: 5 | F36: 最終処分場の廃止基準（ガス発生、内部温度、悪臭）および廃止後の指定区域指定 | G36: 一般廃棄物最終処分場及び産業廃棄物管理型最終処分場の廃止に関する次の記述のうち、最も不適切なものはどれか。 | H36: ① 廃止の基準として、埋立地からガスの発生がほとんど認められないこと又はガスの発生量の増加が2年以上にわたり認められないことが定められている。 | I36: ② 廃止の基準として、埋立地の内部が周辺の地中の温度に比して異常な高温になっていないことが定められている。 | J36: ③ 廃止の基準として、最終処分場の外に悪臭が発散しないように必要な措置が講じられていることが定められている。 | K36: ④ 廃止後は、廃棄物が地下にある土地であって土地の形質の変更により生活環境保全上の支障が生じるおそれがある区域として、指定区域に指定される。 | L36: ⑤ 廃止後は、浸出液処理施設の機能の状態を定期的に点検し、異常を認めた場合には、速やかに必要な措置を講じる必要がある。 | M36: 最終処分場・浸出水

Sheet R5(令和5年度)問題・選択肢
A1: 問題ID | B1: 設問番号 | C1: 大分類(ブロック) | D1: サブジャンル | E1: 公式正答 | F1: 問題のテーマ・内容概要 | G1: 問題文 | H1: 選択肢① | I1: 選択肢② | J1: 選択肢③ | K1: 選択肢④ | L1: 選択肢⑤ | M1: 出題論点（細目）
A2: R5-01 | B2: Ⅲ-1 | C2: 建築環境・設備・建築物衛生管理 | D2: 光・音 | E2: 4 | F2: 北緯35度の日射及び日射調整に関する記述 | G2: 北緯35度の地点の日射及び日射調整に関する次の記述のうち，最も不適切なものはどれか。 | H2: ① 冬至の水平面の終日日射量は，夏至の南鉛直面の終日日射量に比較して多い。 | I2: ② 大気透過率が大きいほど，直達日射が強く，逆に天空日射が弱くなる。 | J2: ③ 東西鉛直面の日射は，日の出・日没付近の，太陽高度の低い状況に対応しているので，日射の調整には庇以外のブラインドなどが必要となる。 | K2: ④ 北鉛直面は，年間を通じて直達日射を受けない。 | L2: ⑤ 南鉛直面の終日日射量は，日射を遮蔽したい夏至のときに最小となる。 | M2: 日照・日射・採光
A3: R5-02 | B3: Ⅲ-2 | C3: 建築環境・設備・建築物衛生管理 | D3: 熱・湿気 | E3: 3 | F3: 建物の伝熱（熱伝導率・断熱材・対流熱伝達率等）に関する記述 | G3: 建物の伝熱に関する次の記述のうち，最も不適切なものはどれか。 | H3: ① 鋼，コンクリートなど密度が1,000kg／m³以上の大きい建築材料は，構造部材として使用される例が多いが，これらの熱伝導率は概ね1W／（m・K）以上で大きく，熱を通しやすい。 | I3: ② 性能の高い断熱材を作るには，固体内部に大量の気体を含み，それらをなるべく微細な空隙に封じ込めるなどして，その流動を抑制する必要がある。 | J3: ③ 屋外風速が3ｍ／ｓの場合，外壁の屋外側の対流熱伝達率は，室内側の対流熱伝達率の値よりも小さい。 | K3: ④ 日射遮蔽係数は，厚さ3ｍｍの透明ガラスの日射熱取得率を基準に各種材料の日射熱取得率を表した値であるため，この値が小さい方が日射遮蔽効果は高い。 | L3: ⑤ 中空層の熱抵抗は，その厚さが2〜5ｃｍ程度までは，厚さを増すほど熱抵抗は増大するが，それ以上ではほとんど変化しない。 | M3: 伝熱・断熱
A4: R5-03 | B4: Ⅲ-3 | C4: 建築環境・設備・建築物衛生管理 | D4: 光・音 | E4: 1 | F4: 視覚・採光基準・直接グレア・明視条件に関する記述 | G4: 光環境に関する次の記述のうち，最も不適切なものはどれか。 | H4: ① ヒトの視覚において，暗所視では，比視感度が最大になる波長が長い方にずれる。 | I4: ② ヒトの視覚において，明順応に比べて，暗順応は時間がかかる。 | J4: ③ 建築基準法における教室及び保育室の採光に有効な窓の基準開口率は，1／5である。 | K4: ④ 直接グレアの防止の基本は，前方視野角の60°以内に高輝度光源を露出させないことである。 | L4: ⑤ 照明設計における明視の条件には，対象の大きさ，対比の大きさ，明るさが含まれる。 | M4: 照明・光環境
A5: R5-04 | B5: Ⅲ-4 | C5: 建築環境・設備・建築物衛生管理 | D5: 光・音 | E5: 5 | F5: 点光源による水平面照度の計算（EA／EBの比） | G5: 下図に示すように光度1,000cdの点光源がある。その直下2ｍの位置にある床上の点Ａの水平面照度をEA［lx］とする。また，点Ａから水平に２ｍ離れた位置の点Ｂの水平面照度をEB［lx］とする。このとき，EA／EBの値に最も近いものはどれか。ただし，この点光源の配光特性は一様であり，水平面照度は壁面等の反射の影響は受けないものとする。 | H5: ① 0.35 | I5: ② 0.71 | J5: ③ 1.00 | K5: ④ 1.41 | L5: ⑤ 2.83 | M5: 照明・光環境
A6: R5-05 | B6: Ⅲ-5 | C6: 建築環境・設備・建築物衛生管理 | D6: 換気・室内空気 | E6: 3 | F6: 室内空気汚染（粉じん・CO2許容濃度・CO発生等）に関する記述 | G6: 室内の空気汚染に関する次の記述のうち，最も不適切なものはどれか。 | H6: ① 粉じんは１〜２μm以下のものが肺胞内に留まって健康被害を及ぼすと考えられていることから，直径10μm以下の粉塵が規制対象となっている。 | I6: ② 必要換気量は室内の汚染物質発生量に対して比例するので，１人当たりm³/hや床面積１m²当たりm³/hのように表示されることが多い。 | J6: ③ 建築基準法や建築物環境衛生管理基準では室内環境における二酸化炭素の許容濃度は1,000ppmであるのに対して，労働環境における二酸化炭素の許容濃度は1,500ppmである。 | K6: ④ 石油ストーブでは，酸素濃度が21%から19%に低下すると，不完全燃焼により急速に一酸化炭素が発生する。 | L6: ⑤ 建材に示されるホルムアルデヒド放散速度とは，建材1m²から１時間当たり放散されるホルムアルデヒド重量を意味する。 | M6: 室内空気質・健康影響・衛生動物
A7: R5-06 | B7: Ⅲ-6 | C7: 建築環境・設備・建築物衛生管理 | D7: 光・音 | E7: 5 | F7: 騒音（屈曲振動・NC値・環境基準・SN比）に関する記述 | G7: 騒音に関する次の記述のうち，最も不適切なものはどれか。 | H7: ① 単一壁に斜めに入射する音波によって，壁体が屈曲振動を起こして透過損失が低下することがある。 | I7: ② 室内騒音の許容値は，騒音レベルLpA［dB］で表した場合の値は，NC値より５〜10大きい。 | J7: ③ 主として住居の用に供せられる地域に対する騒音の環境基準は，昼間55dB以下，夜間45dB以下とされている。 | K7: ④ SN比は，測定対象音のレベル（S［dB］）と暗騒音のレベル（N［dB］）の差（S−N）によって求めることができる。 | L7: ⑤ 室内騒音の許容値は，レストラン，美術館，音楽教室の順で大きくなる。 | M7: 音環境
A8: R5-07 | B8: Ⅲ-7 | C8: 建築環境・設備・建築物衛生管理 | D8: 給排水・防災 | E8: 1 | F8: 水配管システム（三方弁制御・直管圧力損失・ポンプ揚程等）に関する記述 | G8: 水配管システムに関する次の記述のうち，最も不適切なものはどれか。 | H8: ① 三方弁による負荷制御は，負荷が減少すると配管水流量も減少するため，ポンプ動力を節減できる。 | I8: ② 流体が管の断面を充満して流れる場合の直管の圧力損失は，摩擦係数，管の長さ，流体の密度及び流速の２乗に比例し，管の内径に反比例する。 | J8: ③ 開放回路のポンプ揚程は，循環の摩擦損失のほかに押し上げ揚程が加わるので，密閉式に比べてポンプ動力が大きくなる。 | K8: ④ リバースリターン方式は，ファンコイルユニットや放熱器など，同一機種が広い区域に多数連続して設置されるような場合に有効である。 | L8: ⑤ 普通の屋内配管では，浸食による腐食を防ぐための管内流速を一般に2.0m／s以下としている。 | M8: 給水・給湯
A9: R5-08 | B9: Ⅲ-8 | C9: 建築環境・設備・建築物衛生管理 | D9: 空調 | E9: 2 | F9: 外気負荷（顕熱負荷および潜熱負荷）の計算 | G9: 次の条件で冷房している室の外気負荷に関して，顕熱負荷と潜熱負荷の組合せとして，最も適切なものはどれか。 条件： 空気密度：1.2 kg/m³，乾き空気の定圧比熱：1.0 kJ/(kg・K) 外気導入量：400 m³/h，水の蒸発潜熱：2,500 kJ/kg 外気温度：34.0 ℃，室内空気温度：26.0 ℃ 外気絶対湿度：24 g/kg(DA)，室内絶対湿度：12 g/kg(DA) | H9: ① 1,067 W 1,112 W | I9: ② 1,067 W 4,000 W | J9: ③ 3,840 W 14,400 W | K9: ④ 4,000 W 1,067 W | L9: ⑤ 4,000 W 1,112 W | M9: 空調計算（負荷・空気線図・冷凍サイクル）
A10: R5-09 | B10: Ⅲ-9 | C10: 建築環境・設備・建築物衛生管理 | D10: 空調 | E10: 4 | F10: 除湿装置（冷却式・吸収式・吸着式・圧縮式）の原理に関する記述 | G10: 除湿装置に関する次の記述のうち，最も不適切なものはどれか。 | H10: ① 冷却式除湿装置は，処理空気の温度低下と相対湿度の上昇を伴うため，これらが問題となる場合は，冷却除湿後の空気を加熱（再熱）する必要がある。 | I10: ② 吸収式（湿式）除湿装置は，近年は殺菌性を要求される一部食品用途以外はあまり使用されない。 | J10: ③ 吸着式除湿装置は，水分を吸着する性質を持つシリカゲル，活性アルミナ，合成ゼオライト，活性炭などの吸着剤を利用したものである。 | K10: ④ 吸収式（湿式）除湿装置は，ほかの方式に比べて機構が簡単で，安全で金属腐食の問題も少ない。 | L10: ⑤ 圧縮式除湿装置は，空気を圧縮することによって水蒸気の分圧を増加させ，水蒸気の飽和点を超えさせて凝縮分離する方式であり，設備費及び運転費が高くなる。 | M10: 空調機器・ダクト・熱源
A11: R5-10 | B11: Ⅲ-10 | C11: 建築環境・設備・建築物衛生管理 | D11: 給排水・防災 | E11: 3 | F11: 給水方式（直結直圧・直結増圧・圧力水槽・高置水槽・ポンプ直送）に関する記述 | G11: 給水方式に関する次の記述のうち，最も不適切なものはどれか。 | H11: ① 水道直結直圧方式の採用は，夏場など水圧が低くなる時期の水道本管の圧力で決定する必要がある。 | I11: ② 水道直結増圧方式は，供給される水道水の水質劣化や水槽清掃等の衛生上の問題がない上に，省エネルギー効果も期待できる。 | J11: ③ 圧力水槽方式は，水道本管の圧力により圧力水槽内の空気を圧縮・加圧して給水する方式である。 | K11: ④ 高置水槽方式は，給水圧力がほとんど一定である。 | L11: ⑤ ポンプ直送方式は，ポンプやポンプ制御の費用を考えると，小規模建築では設備費が割高になる。 | M11: 給水・給湯
A12: R5-11 | B12: Ⅲ-11 | C12: 建築環境・設備・建築物衛生管理 | D12: 空調 | E12: 4 | F12: 吹出口（スロット型・アネモ型・パン型・ノズル型等）の特性に関する記述 | G12: 吹出口に関する次の記述のうち，最も適切なものはどれか。 | H12: ① スロット型吹出口からの気流は，線源から三次元的に広がる噴流となる。 | I12: ② アネモ型吹出口は，誘引比が小さく拡散性が低いため，コールドドラフトが生じやすい。 | J12: ③ パン型吹出口は，冷房時は下向き吹き出し，暖房時は水平吹き出しが一般的である。 | K12: ④ ノズル型吹出口で，側壁上部から水平に吹き出す場合，暖房時は居住域に滞留域が生じやすい。 | L12: ⑤ 長方形の吹出口からの気流は，アスペクト比（縦横比）が大きいときは円状から円すい状に広がる。 | M12: 空調機器・ダクト・熱源
A13: R5-12 | B13: Ⅲ-12 | C13: 建築環境・設備・建築物衛生管理 | D13: 給排水・防災 | E13: 5 | F13: 大便器の給水方式（洗浄弁・ロータンク）および洗浄方式に関する記述 | G13: 大便器に関する次の記述のうち，最も不適切なものはどれか。 | H13: ① 洗浄弁方式による給水は，最低必要水圧が70kPaである。 | I13: ② ロータンク方式による給水は，最低必要水圧が30kPaである。 | J13: ③ 洗浄方式の分類におけるサイホン式は，洋風便器のみで使用されており，溜水面が広く，汚れにつきにくい。 | K13: ④ 洗浄弁方式は，連続して頻繁に使用される建物に最適である。 | L13: ⑤ 洗浄方式の分類における洗落とし式は，主に和風便器に使用されており，便鉢の水がたまるところに汚物を一時ためて流し出すが，水たまりが浅いため臭気の発散が多い。 | M13: 排水・通気・衛生器具
... A36: R5-35 | B36: Ⅲ-35 | C36: 廃棄物管理 | D36: 最終処分場・浸出水 | E36: 4 | F36: 最終処分場の浸出水処理に関する処理項目と処理方式の組合せ | G36: 最終処分場の浸出水処理に関する処理項目と処理方式の組合せとして，最も不適切なものはどれか。 | H36: ① カルシウムイオン − アルカリ凝集沈殿法 | I36: ② SS − 凝集沈殿法 | J36: ③ ダイオキシン類 − 砂ろ過法 | K36: ④ 塩化物イオン − 精密ろ過法 | L36: ⑤ ふっ素・ほう素 − キレート吸着法 | M36: 最終処分場・浸出水

Sheet R4(令和4年度)問題・選択肢
A1: 問題ID | B1: 設問番号 | C1: 大分類(ブロック) | D1: サブジャンル | E1: 公式正答 | F1: 問題のテーマ・内容概要 | G1: 問題文 | H1: 選択肢① | I1: 選択肢② | J1: 選択肢③ | K1: 選択肢④ | L1: 選択肢⑤ | M1: 出題論点（細目）
A2: R4-01 | B2: Ⅲ-1 | C2: 建築環境・設備・建築物衛生管理 | D2: 光・音 | E2: 4 | F2: 天空日射、日照率、南中時、低鉄分ガラスおよび温室効果に関する記述 | G2: 日照・日射に関する次の記述のうち、最も不適切なものはどれか。 | H2: ① 日射が大気中で散乱されたのち、全天空から地表に到達する成分を天空日射量又は拡散日射量という。 | I2: ② 日照時間の可照時間に対する比を百分率で表したものを日照率という。 | J2: ③ 日本では東経135°（明石）を日本中央標準時の拠点に定めているが、東京は明石よりも早く南中時を迎える。 | K2: ④ 低鉄分ガラスは日射透過率が低い。 | L2: ⑤ 大気中の水蒸気や炭酸ガス、雲などの長波長放射を吸収する特性が、大気の温室効果の原因となっている。 | M2: 日照・日射・採光
A3: R4-02 | B3: Ⅲ-2 | C3: 建築環境・設備・建築物衛生管理 | D3: 光・音 | E3: 5 | F3: 光束法による机上面照度500lx確保のための必要灯数計算 | G3: 床面積が50m²で、机上面照度500lxを確保するには、1灯当たりの光束が2,500lmのランプが何灯必要か。光束法により求めた灯数で最も近い値はどれか。ただし、保守率0.7、照明率0.7とする。 | H3: ① 8灯 | I3: ② 11灯 | J3: ③ 14灯 | K3: ④ 15灯 | L3: ⑤ 21灯 | M3: 照明・光環境
A4: R4-03 | B4: Ⅲ-3 | C4: 建築環境・設備・建築物衛生管理 | D4: 熱・湿気 | E4: 3 | F4: 建築材料の熱伝導率の大きさ順並べ替え | G4: 次のa〜eの建築材料の熱伝導率 [W/(m・K)] について、値の大きいものから順に並べたものはどれか。 a 土壁 b ステンレス鋼 c せっこうボード d グラスウール断熱材16K相当 e コンクリート | H4: ① b, a, c, d, e | I4: ② b, a, e, c, d | J4: ③ b, e, a, c, d | K4: ④ e, b, a, c, d | L4: ⑤ e, b, a, d, c | M4: 伝熱・断熱
A5: R4-04 | B5: Ⅲ-4 | C5: 建築環境・設備・建築物衛生管理 | D5: 温熱・省エネ指標 | E5: 2 | F5: PMV、PPD、新有効温度(ET*)、体温調節機構および不感蒸せつ | G5: 人体の熱収支及び温熱感覚指標に関する次の記述のうち、最も不適切なものはどれか。 | H5: ① 予測平均温冷感申告PMVと予測不満足率PPDはISOにおける標準的温熱感覚指標として採用されており、−0.5≦PMV≦0.5、PPD≦10%が推奨範囲とされている。 | I5: ② 予測平均温冷感申告PMVは新有効温度ET*よりも暑熱環境評価を正確に行うことができると考えられている。 | J5: ③ 体温調整機構において、皮膚血流の調整によるコア・シェル部の大きさ変化で体温調整が可能な領域を中性温域という。 | K5: ④ 各種作業時の代謝量はmetを単位として表すが、1metは体表面積当たりの椅座安静状態での代謝量であり58.2W/m²である。 | L5: ⑤ 発汗していない状態でも、絶えず人体の皮膚や粘膜からは水分蒸発による放熱が起きており、これを「不感蒸せつ」という。 | M5: 温熱環境・温熱指標
A6: R4-05 | B6: Ⅲ-5 | C6: 建築環境・設備・建築物衛生管理 | D6: 光・音 | E6: 2 | F6: 残響時間、音波の回折、音調(pitch)、可聴周波数範囲およびマスキング効果 | G6: 音波と聴覚に関する次の記述のうち、最も不適切なものはどれか。 | H6: ① 残響時間は室の容積が大きいほど長くなり、吸音する材料や物体が多いほど短くなる。 | I6: ② 音波の回折による減衰は波長が物体の寸法に比べ、長い場合は大きく、短い場合は小さい。 | J6: ③ 連続音の調子（pitch）は主として周波数に関係し、周波数の小さい音は低く感じる。 | K6: ④ 音として聞こえる周波数の範囲は、その強さによって変わるが、大体20〜20,000Hzである。 | L6: ⑤ ある音を聞こうとするとき、騒音が同時に存在すると、非常に聞きにくくなることをマスキング効果と呼ぶ。 | M6: 音環境
A7: R4-06 | B7: Ⅲ-6 | C7: 建築環境・設備・建築物衛生管理 | D7: 熱・湿気 | E7: 3 | F7: 結露の定義、断熱材の配置、防湿層の位置、絶対湿度および二重ガラスサッシ | G7: 結露とその対策に関する次の記述のうち、最も不適切なものはどれか。 | H7: ① 室内の温度の高い湿り空気が、その空気の露点温度以下の冷たい壁や天井に触れ、水蒸気が凝集する現象のことを結露という。 | I7: ② 断熱材貼付により断熱材の高温側は結露しにくくなり、低温側は結露しやすくなる。 | J7: ③ 外壁において、防湿層を断熱層の屋外側に設けることは、内部結露を防止する効果がある。 | K7: ④ 絶対湿度は気密に仕切られていない限り、暖房室、非暖房室で同じになる傾向にあるので、室温の低い室内で結露が発生しやすい。 | L7: ⑤ 窓ガラスの室内側にカーテンを設けることは、冬期におけるガラス面の結露の防止対策として期待できない。 | M7: 結露・湿気・湿り空気
A8: R4-07 | B8: Ⅲ-7 | C8: 建築環境・設備・建築物衛生管理 | D8: 換気・室内空気 | E8: 2 | F8: トレーサーガス法（定常放出法、減衰法）の原理および適用条件 | G8: 室内空間において、瞬間一様拡散が仮定できる状況下で人為的にガスを発生させ、その濃度を測定するトレーサーガス法に関する次の記述のうち、最も不適切なものはどれか。 | H8: ① トレーサーガス法は、トレーサーガスが空間の壁などに吸われやすかったり、吸着したりしないことを仮定している。 | I8: ② トレーサーガス法は、空間の開口部や隙間が数多く分散しており、そこでの空気の流出入が不明確であるような自然換気の測定には用いることができない。 | J8: ③ トレーサーガスには、空気と比重が比較的近く、濃度測定が簡易なガスが用いられる。 | K8: ④ トレーサーガスを空間内に一定割合で人為的に連続放出し、その定常状態の濃度を測定することで、換気量を得ることができる。 | L8: ⑤ トレーサーガスを空間内に放出し、均一な濃度分布を達成した後の濃度変化を測定することで、換気量を得ることができる。 | M8: 換気・通風
A9: R4-08 | B9: Ⅲ-8 | C9: 建築環境・設備・建築物衛生管理 | D9: 換気・室内空気 | E9: 1 | F9: 定常状態の質量流量、温度差換気、風圧換気および中性帯位置の基本特性 | G9: 空気流動に関する次の記述のうち、最も適切なものはどれか。 | H9: ① 定常状態において、外部から室内に流入する空気の質量流量は、室内から外部へ流出する空気の質量流量と同じである。 | I9: ② 冬期において、室内の温度より外気温の方が低い場合、屋内外の温度差によって、上部には外気が流入する力が生じ、下部には室内の空気が流出する力が生じる。 | J9: ③ 風圧力によって換気される場合、その換気量は、外部風向と開口条件が一定ならば、外部風速の平方根に比例する。 | K9: ④ 外気に面して異なる高さに同じ大きさの2つの開口部がある室において、無風の条件で温度差換気を行う場合、換気量は内外温度差の2乗に比例する。 | L9: ⑤ 大きさの異なる上下の2つの開口部を用いて、無風の条件で温度差換気を行う場合、中性帯の位置は、有効開口面積の小さい方の開口部に近づく。 | M9: 換気・通風
A10: R4-09 | B10: Ⅲ-9 | C10: 建築環境・設備・建築物衛生管理 | D10: 温熱・省エネ指標 | E10: 5 | F10: 相当外気温度、ナイトパージ、内耐熱、局所空調および放射熱移動の絶対温度依存性 | G10: 建物の温熱環境に関する次の記述のうち、最も不適切なものはどれか。 | H10: ① 定常状態を想定した日射が当たる外壁では、外気温を相当外気温度に置き換えて計算すれば、日射の影響を考慮した貫流熱量が求められる。 | I10: ② ナイトパージにより冷気を室内に導入し、外気が保持する冷熱を躯体に蓄熱させ、昼間の冷房の用に供することができる。 | J10: ③ 内断熱は蓄熱負荷を小さく抑え、予熱時には、室温及び壁体の室内表面温度を速やかに所定のレベルに到達させることができる。 | K10: ④ アトリウムや大空間などでは、人間が居住する範囲だけを局所的・効果的に空調することが望まれる。 | L10: ⑤ 物体間の放射による熱移動量は、それぞれの物体表面の絶対温度の3乗の差に比例する。 | M10: 温熱環境・温熱指標
A11: R4-10 | B11: Ⅲ-10 | C11: 建築環境・設備・建築物衛生管理 | D11: 給排水・防災 | E11: 4 | F11: 大便器フラッシュバルブ必要圧力、受水槽スペース、逆サイホン防止およびトラップ封水深 | G11: 給排水設備に関する次の記述のうち、最も不適切なものはどれか。 | H11: ① 大便器に使用する洗浄弁（フラッシュバルブ）の必要圧力は、ゲージ圧で0.07MPa以上である。 | I11: ② 受水槽は保守・点検のため、標準的には上部に1m以上、周囲・下部に0.6m以上のスペースを設けなくてはならない。 | J11: ③ 給水系統への逆サイホン作用による汚水の逆流を防止するために、洗面器に吐水口空間（エアギャップ）を設ける。 | K11: ④ 排水トラップの最大封水深は50mmである。 | L11: ⑤ 給水管の圧力損失には、直管による摩擦損失以外に、継手や弁類などによる圧力損失があるが、これらの圧力損失はいずれも流速の2乗に比例して増大する。 | M11: 排水・通気・衛生器具
A12: R4-11 | B12: Ⅲ-11 | C12: 建築環境・設備・建築物衛生管理 | D12: 空調 | E12: 1 | F12: 圧縮式冷凍機のモリエル線図における圧縮過程・蒸発過程および成績係数(COP) | G12: 次の記述の、[ ア ]〜[ ウ ]に入る記号又は数式の組合せとして、最も適切なものはどれか。 「下図のモリエ（モリエル）線図に示す圧縮式冷凍機の冷凍サイクルにおいて、[ ア ] は蒸発過程を、[ イ ] は圧縮過程をそれぞれ示しており、この冷凍機としての理論成績係数は [ ウ ] で表される。」 | H12: ① ア: 1→2, イ: 2→3, ウ: (h2-h1)/(h3-h2) | I12: ② ア: 4→1, イ: 3→4, ウ: (h3-h2)/(h2-h1) | J12: ③ ア: 3→4, イ: 1→2, ウ: (h3-h1)/(h3-h2) | K12: ④ ア: 1→2, イ: 3→4, ウ: (h2-h1)/(h3-h1) | L12: ⑤ ア: 4→1, イ: 2→3, ウ: (h3-h2)/(h3-h1) | M12: 空調計算（負荷・空気線図・冷凍サイクル）
A13: R4-12 | B13: Ⅲ-12 | C13: 建築環境・設備・建築物衛生管理 | D13: 給排水・防災 | E13: 3 | F13: 防煙区画、自然排煙、水平区画面積上限（500㎡）および排煙ダクト工事 | G13: 排煙設備に関する次の記述のうち、最も不適切なものはどれか。 | H13: ① 防煙区画は、煙感知器の作動を確実にするような効果も期待できる。 | I13: ② 自然排煙は、一般の事務室のように天井高さが低く、換気経路も明確でない場合には有効な排煙効果は期待できない。 | J13: ③ 防煙区画（水平区画）の面積は、最大100m²である。 | K13: ④ 機械排煙設備の手動開放装置を壁面に設ける場合は、床面より0.8〜1.5mの高さとする。 | L13: ⑤ 天井チャンバ方式の排煙設備は、同一排煙区画内であれば、間仕切り変更に対して排煙ダクト工事が不要となる。 | M13: 防災・排煙・消火
A14: R4-13 | B14: Ⅲ-13 | C14: 建築環境・設備・建築物衛生管理 | D14: 空調 | E14: 5 | F14: 室内の顕熱負荷6.6kWにおける空調機吹出し風量[m³/h]および除湿量[kg/h]計算 | G14: 室内空気を空調機の熱交換器に通して冷却・減湿（除湿）した。室内の顕熱負荷が6.6kWのとき、空調機の吹出し風量と除湿量との組合せとして、最も適切なものは次のうちどれか。ただし、与条件は以下とする。 室内空気（空調機の入口）条件：温度26℃、絶対湿度0.011 kg/kg(DA) 吹出し（空調機の出口）条件：温度15℃、絶対湿度0.009 kg/kg(DA) 空気の比熱：1.2 kJ/(m³・K) 空気の比体積（比容積）：0.83 m³/kg(DA) | H14: ① 吹出し風量: 550 m³/h, 除湿量: 1.2 kg/h | I14: ② 吹出し風量: 1320 m³/h, 除湿量: 2.2 kg/h | J14: ③ 吹出し風量: 1320 m³/h, 除湿量: 3.2 kg/h | K14: ④ 吹出し風量: 1800 m³/h, 除湿量: 3.0 kg/h | L14: ⑤ 吹出し風量: 1800 m³/h, 除湿量: 4.3 kg/h | M14: 空調計算（負荷・空気線図・冷凍サイクル）
A15: R4-14 | B15: Ⅲ-14 | C15: 建築環境・設備・建築物衛生管理 | D15: 換気・室内空気 | E15: 5 | F15: 越冬昆虫侵入メカニズム、クマネズミ駆除、コナヒョウヒダニおよびゴキブリ体内時計 | G15: 建築物におけるねずみ・害虫対策に関する次の記述のうち、最も不適切なものはどれか。 | H15: ① 外気温が低くなると、外壁に内部から伝わる熱や、隙間から漏れる熱を感じて、越冬等の目的で昆虫等が侵入しやすくなる。 | I15: ② ねずみの駆除は、餌を断つこと、通路を遮断すること、巣を作らせないことを基本に進める。 | J15: ③ 居住環境で見られるコナヒョウヒダニやヤケヒョウヒダニは、ヒトを刺したり吸血したりすることはないが、そのふんや死骸は喘息やアトピー性皮膚炎の原因となることがある。 | K15: ④ ゴキブリは、夜間、潜伏場所から出現し、摂食、摂水行動を起こし、体内に組み込まれた体内時計により、約24時間を周期とする行動が見られる。 | L15: ⑤ イエバエ、クロバエ、ニクバエ類等の中・大型のハエ類は、厨芥等の処理がきちんと行われていても、幼虫が発生する。 | M15: 室内空気質・健康影響・衛生動物
A16: R4-15 | B16: Ⅲ-15 | C16: 建築環境・設備・建築物衛生管理 | D16: 換気・室内空気 | E16: 2 | F16: 二面開口住戸における風力換気量[m³/s]の計算 | G16: 下図に示す二面開口住戸の風力換気量に最も近い値はどれか。ただし、外部風速（v）、各開口部の風圧係数（C）、実効面積（αA）は下図に示す値とする。 外部風速 v＝4 m/s 開口部1: α1A1＝2 m², C1＝＋0.6 開口部2: α2A2＝2 m², C2＝−0.3 | H16: ① 5.1 m³/s | I16: ② 5.4 m³/s | J16: ③ 7.6 m³/s | K16: ④ 20.4 m³/s | L16: ⑤ 21.5 m³/s | M16: 換気・通風
A17: R4-16 | B17: Ⅲ-16 | C17: 建築環境・設備・建築物衛生管理 | D17: 建築物衛生法・レジオネラ | E17: 4 | F17: 保健所の役割、免状交付、特定建築物定義および所有者の受任義務 | G17: 建築物における衛生的な環境の確保に関する法律（建築物衛生法）に関する次の記述のうち、最も不適切なものはどれか。 | H17: ① 保健所は、多数の者が使用し、又は利用する建築物の維持管理について、環境衛生上の正しい知識の普及に努めるとともに、環境衛生上の相談に応じ、必要な指導を行う。 | I17: ② 建築物環境衛生管理技術者免状は、厚生労働大臣の登録を受けた者が行う講習会の課程を修了したもの又は、建築物環境衛生管理技術者試験に合格した者に対し、厚生労働大臣が交付する。 | J17: ③ 建築物衛生法が定める「特定建築物」に、病院の用に供される建築物は含まれない。 | K17: ④ 建築物衛生法が定める「特定建築物」は、定められた用途の用に供される部分の延べ面積が2,000平方メートル以上の建築物である。 | L17: ⑤ 特定建築物所有者等は、建築物環境衛生管理技術者免状を有する者を建築物環境衛生管理技術者に選任しなければならない。 | M17: 建築物衛生法・衛生基準
A18: R4-17 | B18: Ⅲ-17 | C18: 建築環境・設備・建築物衛生管理 | D18: 換気・室内空気 | E18: 1 | F18: スギ花粉の粒子径（30μm）、飛散量と気温・湿度の相関、床材の清掃性 | G18: スギ花粉に関する次の記述のうち、最も不適切なものはどれか。 | H18: ① スギ花粉として認識される粒子の大きさは直径約3μmで、ほぼ球状の粒子である。 | I18: ② 花粉飛散数は気温との相関が高く、また、湿度が低下するに従い飛散数は増加し、風速が強くなれば多数の花粉が飛散する。 | J18: ③ 花粉の室内における高さ別落下量は、床面に近いほど多い。 | K18: ④ 床材は堆積花粉の除去のしやすさを考慮すると、毛足の長いカーペットよりフローリングの方が望ましい。 | L18: ⑤ 空中花粉の捕集方法は、単位面積・単位時間内に自然落下する花粉を捕集する「落下法」と 定量の空気中に含まれる花粉を捕集する「体積法」に大別される。 | M18: 室内空気質・健康影響・衛生動物
A19: R4-18 | B19: Ⅲ-18 | C19: 建築環境・設備・建築物衛生管理 | D19: 換気・室内空気 | E19: 3 | F19: 住宅内のカビ栄養源、夏季換気制限、カビの好むpH(酸性〜中性)およびCFU単位 | G19: 室内におけるカビに関する次の記述のうち、最も不適切なものはどれか。 | H19: ① 住宅内の壁紙、塗料、木材のほとんどはカビの栄養源となり、温度、特に湿度条件が整えば増殖する。 | I19: ② 外気の湿度条件としてすでにカビの発生可能な夏期は、換気しても室内はカビの発生可能な状態が続くので、カビの防止には室内の絶対湿度を下げる必要がある。 | J19: ③ カビはpH（水素イオン濃度）では、酸性や中性を好み、アルカリ性では生育しない。 | K19: ④ カビの測定は、培地の準備、捕集（サンプリング）、培養及び計数などを経てカビの汚染度合いを評価する。 | L19: ⑤ カビの数を表す単位としては、CFU（colony forming unit）が用いられ、捕集されたカビが培地の表面で一定の温湿度条件と培養期間において増殖し、肉眼で確認できるような1つの集落（コロニー）を1CFUという。 | M19: 室内空気質・健康影響・衛生動物
... A36: R4-35 | B36: Ⅲ-35 | C36: 廃棄物管理 | D36: 最終処分場・浸出水 | E36: 4 | F36: 最終処分場埋立終了後の維持管理継続（水処理・ガス抜き）および跡地利用 | G36: 一般廃棄物最終処分場及び産業廃棄物管理型最終処分場の埋立終了後の扱いに関する次の記述のうち、最も不適切なものはどれか。 | H36: ① 跡地利用として、太陽光発電を導入した事例がある。 | I36: ② 公園・スポーツ広場・農園等として跡地利用されている。 | J36: ③ 埋立終了後においても、排水処理やガス抜き等の維持管理を継続する必要がある。 | K36: ④ 埋立終了した埋立地は、厚さがおおむね1m以上の土砂及び遮水シートにより開口部を閉鎖する必要がある。 | L36: ⑤ 廃止された最終処分場は、廃棄物処理施設として維持管理を行わなくとも、そのまま生活環境保全上の問題が生じるおそれがない状態である。 | M36: 最終処分場・浸出水

Sheet R3(令和3年度)問題・選択肢
A1: 問題ID | B1: 設問番号 | C1: 大分類(ブロック) | D1: サブジャンル | E1: 公式正答 | F1: 問題のテーマ・内容概要 | G1: 問題文 | H1: 選択肢① | I1: 選択肢② | J1: 選択肢③ | K1: 選択肢④ | L1: 選択肢⑤ | M1: 出題論点（細目）
A2: R3-01 | B2: Ⅲ-1 | C2: 建築環境・設備・建築物衛生管理 | D2: 熱・湿気 | E2: 4 | F2: 湿り空気の全圧、露点温度、絶対湿度、相対湿度および平衡状態に関する正誤判定 | G2: 湿り空気に関する次の記述のうち，最も不適切なものはどれか。 | H2: ① 乾き空気の分圧と水蒸気分圧を加算したものが湿り空気の全圧となる。 | I2: ② 水蒸気の多く含まれている空気ほど，露点温度は高くなる。 | J2: ③ 相対湿度は温度変化の影響を受けるが，絶対湿度は温度変化の影響を受けない。 | K2: ④ 空気中の相対湿度が50%のとき，湿球温度は乾球温度と同じ値になる。 | L2: ⑤ 一定時間に水面から飛び出す水蒸気分子の数と，湿り空気から水面に飛び込む水蒸気分子の数が同数になるとき，これを平衡状態という。 | M2: 結露・湿気・湿り空気
A3: R3-02 | B3: Ⅲ-2 | C3: 建築環境・設備・建築物衛生管理 | D3: 熱・湿気 | E3: 5 | F3: 放射エネルギー、対流熱伝達率、キルヒホッフの法則、水蒸気拡散およびルイスの法則に関する正誤判定 | G3: 伝熱・物質伝達に関する次の記述のうち，最も不適切なものはどれか。 | H3: ① 全ての物体は，絶対温度でない限りその温度に応じた放射エネルギーを出しており，その放射量は絶対温度の4乗に比例する。 | I3: ② 室内の対流熱伝達率は，暖房時の天井面と冷房時の床面は大きく，冷房時の天井面と暖房時の床面は小さい値が用いられる。 | J3: ③ 同一波長に対して放射率と吸収率が等しくなる性質を，キルヒホッフの法則という。 | K3: ④ ドアや襖で仕切られていても水蒸気は容易に隣室に拡散するため，住戸内はほぼ一様な絶対湿度になる。 | L3: ⑤ 濡れた物体表面から周囲空気へ水が蒸発するプロセスは対流熱伝達と相似性があり，これをフィックの法則という。 | M3: 伝熱・断熱
A4: R3-03 | B4: Ⅲ-3 | C4: 建築環境・設備・建築物衛生管理 | D4: 光・音 | E4: 5 | F4: 残響時間、障壁の回折効果、コインシデンス効果、重量床衝撃音および多孔質吸音材に関する正誤判定 | G4: 音環境に関する次の記述のうち，最も不適切なものはどれか。 | H4: ① 音響エネルギー密度が60dBだけ減衰するのに要する時間を残響時間という。 | I4: ② 障壁は，回折による高音域の遮断に対する効果が大きい。 | J4: ③ コインシデンス効果は，音が様々な方向から壁面に入射する場合には広い周波数で発生する。 | K4: ④ 重量衝撃音の低減に対しては，床構造の曲げ剛性や質量が重要で，木造などの軽量床の場合，必要な性能を得ることは困難である。 | L4: ⑤ 多孔質材の吸音機構において，剛壁に直貼りしたときの吸音率は，吸音材の材厚を厚くしても，低音域の吸音率は向上しない。 | M4: 音環境
A5: R3-04 | B5: Ⅲ-4 | C5: 建築環境・設備・建築物衛生管理 | D5: 換気・室内空気 | E5: 2 | F5: 吸込み気流の指向性、換気回数計算、空気寿命・空気余寿命、重力換気および第1種・第2種換気に関する正誤判定 | G5: 換気に関する次の記述のうち，最も不適切なものはどれか。 | H5: ① 給気口周りの気流と排気口周りの気流の様子は大きく異なり，吹出し気流には指向性があるが，吸込み気流には指向性がない。 | I5: ② 30分毎に一度窓を開けて換気を行う場合，換気回数は2回／hとなる。 | J5: ③ 給気口から出た新鮮空気が室内のある点Pに到達するまでの時間を空気齢，ある点Pの空気が排気口に至るまでの時間を空気余命，空気齢と空気余命の和を空気寿命と呼ぶ。 | K5: ④ 重力換気を行う場合，上部と下部の開口のレベル差と建物内外の温度差が大きいほど，換気量は大きくなる。 | L5: ⑤ 手術室やクリーンルームなどのように，周囲から汚染空気が流入してはならない室では，室内圧を周囲より高く保つように第2種機械換気とするか，給気量より排気量の少ない第1種機械換気とする。 | M5: 換気・通風
A6: R3-05 | B6: Ⅲ-5 | C6: 建築環境・設備・建築物衛生管理 | D6: 熱・湿気 | E6: 1 | F6: 各種建築材料（押出発泡ポリスチレン、合板、ガラス、コンクリート、ステンレス鋼）の熱伝導率比較順序の判定 | G6: 次の (a) 〜 (e) の建築材料の熱伝導率 [W/m・K] について，値の小さいものから順に並べたものはどれか。 (a) ガラス (b) コンクリート (c) 合板 (d) ステンレス鋼 (e) 押出発泡ポリスチレン | H6: ① e, c, a, b, d | I6: ② e, a, c, b, d | J6: ③ e, a, c, d, b | K6: ④ c, e, b, a, d | L6: ⑤ c, e, b, d, a | M6: 伝熱・断熱
A7: R3-06 | B7: Ⅲ-6 | C7: 建築環境・設備・建築物衛生管理 | D7: 光・音 | E7: 3 | F7: 日射の波長区分、散乱・天空放射、CO2による吸収、短波長・長波長透過性および実効放射に関する正誤判定 | G7: 日射に関する次の記述のうち，最も不適切なものはどれか。 | H7: ① 日射はその波長によって，200〜380nmの紫外線，380〜780nmの可視線，780〜10⁵nmの赤外線に大別される。 | I7: ② 散乱は放射線が空気粒子により散乱させられる現象で，散乱されたものの約半分は地表に到達し，天空放射と呼ばれる。 | J7: ③ 大気中での日射の吸収は主としてCO2により行われ，水蒸気もわずかながら吸収する。 | K7: ④ 大気は直達・天空放射のような比較的短波長の放射はよく透過するが，地面放射のような長波長の放射はほとんど吸収する。 | L7: ⑤ 地面放射と大気放射の差を実効放射又は夜間放射と呼ぶ。 | M7: 日照・日射・採光
A8: R3-07 | B8: Ⅲ-7 | C8: 建築環境・設備・建築物衛生管理 | D8: 給排水・防災 | E8: 4 | F8: 排煙方式、泡消火設備、補助散水栓、建築基準法・消防法における排煙目的およびスプリンクラー設備に関する正誤判定 | G8: 建物の防災設備に関する次の記述のうち，最も適切なものはどれか。 | H8: ① 特別避難階段の付室の排煙は，自然排煙方式でなければならない。 | I8: ② 泡消火設備は，泡消火剤と水の混合液を泡ヘッドなどの発泡器に送り，空気を吸引して発生させた泡を放射して，泡の冷却作用により消火する設備である。 | J8: ③ 補助散水栓は，消防法によりスプリンクラーヘッドの設置を免除されている未警戒部分を防護するために設置されるもので，アラーム弁の一次側配管から分岐する。 | K8: ④ 建築基準法上の排煙設備は避難安全確保を主目的とし，消防法上の排煙設備は消火活動支援を主目的としている。 | L8: ⑤ スプリンクラー設備では，天井面や壁面に取り付けたヘッドから散水し，その窒息作用により消火する。 | M8: 防災・排煙・消火
A9: R3-08 | B9: Ⅲ-8 | C9: 建築環境・設備・建築物衛生管理 | D9: 換気・室内空気 | E9: 4 | F9: 換気・除湿・室内外温湿度条件に基づく室内水蒸気発生量の定型計算 | G9: 室内外の換気量が50m³/hのときに，室内の絶対湿度が8g/kg(DA)に保たれている状態での室内水蒸気発生量に最も近い値はどれか。ただし，室内は除湿器によって50g/hの除湿がなされており，室温と外気温度は共に20℃，外気絶対湿度が3g/kg(DA)，空気密度 ρ = 1.2 kg(DA)/m³ とする。 | H9: ① 250 [g/h] | I9: ② 258 [g/h] | J9: ③ 300 [g/h] | K9: ④ 350 [g/h] | L9: ⑤ 530 [g/h] | M9: 換気・通風
A10: R3-09 | B10: Ⅲ-9 | C10: 建築環境・設備・建築物衛生管理 | D10: 空調 | E10: 3 | F10: 風量制御、床吹出し空調、Low-eガラスの配置、ヒートポンプ加熱および全熱交換器に関する正誤判定 | G10: 省エネルギーに関する次の記述のうち，最も不適切なものはどれか。 | H10: ① 変風量方式の風量制御は，ダンパ制御より回転数制御の方が省エネルギー効果が大きい。 | I10: ② 床吹出し空調方式では，冷房運転時の吹出し温度が天井吹出し方式より高いので，冷熱源の運転や外気冷房などが効率的に行える。 | J10: ③ 近代的なオフィスビルで，冷房負荷軽減のためLow-eガラスを複層ガラスの室内側に採用することが多い。 | K10: ④ ヒートポンプ加熱は熱源から得た熱を利用し，暖房負荷より少ない投入エネルギーで暖房ができる。 | L10: ⑤ 全熱交換器は，空調の外気負荷のピークロードの減少により，冷凍機・ボイラ・付属機器の容量を小さくできる。 | M10: 空調方式・省エネルギー
A11: R3-10 | B11: Ⅲ-10 | C11: 建築環境・設備・建築物衛生管理 | D11: 給排水・防災 | E11: 5 | F11: 配管流速、ポンプ全揚程、高層建築の圧力ゾーニング、水道直結直圧方式および飲料用開放水槽の保有距離に関する正誤判定 | G11: 給水設備に関する次の記述のうち，最も不適切なものはどれか。 | H11: ① 配管に流れる流量から，流水音やウォーターハンマーを生じさせないため，管内の流速は1.5〜2.0m/s以下が望ましい。 | I11: ② 揚水ポンプの全揚程は，実揚程と摩擦損失水頭と速度水頭の総和以上となる必要がある。 | J11: ③ 高層建築では，低層の各階の分岐管に減圧弁を設置する各階減圧弁方式と呼ばれる圧力ゾーニングの方式がある。 | K11: ④ 水道直結直圧方式は，高圧配水システムを採用している水道事業体では，4〜5階程度の建物まで採用されている。 | L11: ⑤ 飲料用開放水槽の設置においては，隣接する他の機器や壁との距離は30cm以上確保する必要がある。 | M11: 給水・給湯
A12: R3-11 | B12: Ⅲ-11 | C12: 建築環境・設備・建築物衛生管理 | D12: 空調 | E12: 2 | F12: エアフロー・ウィンドウ、デシカント空調、スクリュー式冷凍機、ビル用マルチパッケージおよび氷蓄熱に関する正誤判定 | G12: 空気調和設備に関する次の記述のうち，最も不適切なものはどれか。 | H12: ① エアフローウィンドウは，ペリメータ処理方式と異なりファンコイルユニットや水配管を室内に持ち込まないので，施工や維持管理の面でメリットがある。 | I12: ② デシカント空調における除湿は，空気を冷却することで，水を凝縮して分離している。 | J12: ③ 中小規模の建物ではスクリュー式冷凍機が多く用いられる。 | K12: ④ ビル用マルチパッケージ方式において外調機を設ける場合，適用するフィルタの性能は，目的とする室の空気質，室の発じん量，外気の空気質から決定する。 | L12: ⑤ 熱源によって生成された冷温熱を蓄える蓄熱槽のうち，氷蓄熱では，同じ熱量なら水蓄熱より容積が小さくて済む。 | M12: 空調方式・省エネルギー
A13: R3-12 | B13: Ⅲ-12 | C13: 建築環境・設備・建築物衛生管理 | D13: 給排水・防災 | E13: 1 | F13: バリアフリー新法における衛生器具設置基準、小便器節水量、大便器洗浄弁最高給水圧力、ハンドシャワーのバキュームブレーカーおよび耐圧試験水圧に関する正誤判定 | G13: 衛生器具に関する次の記述のうち，最も不適切なものはどれか。 | H13: ① バリアフリー新法により，デパートなど不特定多数の者が利用する施設等では，オストメイトと床置き，又は受け口の高さが500mm以下の壁掛け式の小便器を1つずつ以上設ける必要がある。 | I13: ② 小便器は，従来4L/回の洗浄水量であったが，近年は1.2L/回程度に節水されている。 | J13: ③ 大便器洗浄弁を使用する際の最高給水圧力は，400kPaまでとすることが望ましい。 | K13: ④ 浴室のハンドシャワーが浴槽内に水没した場合に，浴槽内等の汚れた水が逆流して上水を汚染しないよう，必ずバキュームブレーカーを取り付ける。 | L13: ⑤ JISによる給水栓の場合，1.75MPaの試験水圧に耐えるものでなければならない。 | M13: 排水・通気・衛生器具
... A36: R3-35 | B36: Ⅲ-35 | C36: 廃棄物管理 | D36: 災害廃棄物・事業方式・統計・管理票 | E36: 1 | F36: 災害廃棄物の定義・処理主体（市町村が主体）、災害廃棄物対策指針、処理計画、仮置場確保および災害廃棄物処理支援ネットワークに関する正誤判定 | G36: 災害廃棄物に関する次の記述のうち，最も不適切なものはどれか。 | H36: ① 災害廃棄物は，自然災害に直接起因して発生する廃棄物のうち，自然環境保全上の支障へ対処するため，市区町村等がその処理を実施するものである。 | I36: ② 災害廃棄物対策指針は，環境省が災害廃棄物処理計画の策定及び災害廃棄物対策を実施する際の参考となる災害廃棄物対策の基本的事項を取りまとめたものである。 | J36: ③ 災害廃棄物処理計画は，地方公共団体が災害廃棄物を適正かつ円滑・迅速に処理するために必要な事項を整理したものである。 | K36: ④ 災害廃棄物処理計画には，発災時における仮置場の確保，分別自体の徹底，処理先の確保等の必要事項を取りまとめる。 | L36: ⑤ 災害廃棄物処理支援ネットワークは，我が国の災害廃棄物対応力を向上させるため，災害廃棄物対策のエキスパートで構成される組織である。 | M36: 災害廃棄物・指定廃棄物

Sheet R2(令和2年度)問題・選択肢
A1: 問題ID | B1: 設問番号 | C1: 大分類(ブロック) | D1: サブジャンル | E1: 公式正答 | F1: 問題のテーマ・内容概要 | G1: 問題文 | H1: 選択肢① | I1: 選択肢② | J1: 選択肢③ | K1: 選択肢④ | L1: 選択肢⑤ | M1: 出題論点（細目）
A2: R2-01 | B2: Ⅲ-1 | C2: 建築環境・設備・建築物衛生管理 | D2: 換気・室内空気 | E2: 4 | F2: 二向開口住戸における風上・風下開口部の合成相当開口面積計算 | G2: 二面開口住戸の通風・換気性能について，風上開口の相当開口面積 α1A1，風下開口の相当開口面積 α2A2, α3A3 が下図に示す値である場合，これらを合成した相当開口面積（合成 αA）に最も近い値はどれか。［図：α1A1＝100cm²，α2A2＝50cm²，α3A3＝50cm²］ | H2: ① 14 [cm²] | I2: ② 24 [cm²] | J2: ③ 33 [cm²] | K2: ④ 71 [cm²] | L2: ⑤ 135 [cm²] | M2: 換気・通風
A3: R2-02 | B3: Ⅲ-2 | C3: 建築環境・設備・建築物衛生管理 | D3: 光・音 | E3: 5 | F3: 明順応・暗順応、直接グレア防止、教室の採光有効面積および暗所視の比視感度最大波長に関する正誤判定 | G3: 光環境に関する次の記述のうち，最も不適切なものはどれか。 | H3: ① ヒトの視覚において，明順応に比べて，暗順応は時間がかかる。 | I3: ② 直接グレアの防止の基本は，前方視野角の30°以内に高輝度光源を露出させないことである。 | J3: ③ 建築基準法における教室（幼稚園・小学校・中学校・高等学校又は中等教育学校）の採光のための窓，その他の開口部の採光に有効な部分の面積は，床面積の1／5以上である。 | K3: ④ 照明設計における明視の条件は，視角が大きいこと，対比の大きいこと，動きのないこと，明るいことであるが，特に明るさが重要である。 | L3: ⑤ ヒトの視覚において，暗所視では，比視感度が最大になる波長が長い方にずれる。 | M3: 照明・光環境
A4: R2-03 | B4: Ⅲ-3 | C4: 建築環境・設備・建築物衛生管理 | D4: 温熱・省エネ指標 | E4: 2 | F4: 居室の断熱性能、暖房時の室内空気・壁表面温度差および外断熱蓄熱効果に関する正誤判定 | G4: 住宅の居室の冬期室内温熱環境及び間欠暖房に関する次の記述のうち，最も不適切なものはどれか。 | H4: ① 同じ熱容量の場合，断熱性能を向上させると，暖房停止後の室温低下が穏やかとなる。 | I4: ② 居室の断熱性能が低いと，暖房時の室内空気温度と壁の室内側表面温度の差が小さくなる。 | J4: ③ 同じ熱容量の場合，断熱性能を向上させると，立上り負荷が小さくなる。 | K4: ④ 居室の断熱性能が低いと，より多量の熱量を投入する必要が生じ，天井付近に高温の空気が停滞して上下温度差がつきやすくなる。 | L4: ⑤ コンクリートなどの熱容量の大きな材料で作られた構造体の蓄熱効果を活用するためには，外断熱でなければならない。 | M4: 温熱環境・温熱指標
A5: R2-04 | B5: Ⅲ-4 | C5: 建築環境・設備・建築物衛生管理 | D5: 光・音 | E5: 3 | F5: 板振動型・多孔質型吸音機構、複層ガラスの遮音特性およびコインシデンス効果に関する正誤判定 | G5: 各種材料の遮音性能に関する次の記述のうち，最も不適切なものはどれか。 | H5: ① 板振動型吸音機構では，低音域の共振周波数付近で吸音率は高く，中高音域の吸音率は小さい。 | I5: ② 多孔質型吸音機構では，波長の長い低音に対して吸音率を高めるためには，材料を厚くするか剛壁から離して設置する必要がある。 | J5: ③ ガラスの厚さを合計して6mmとし，面密度を一定とした場合，複層ガラス窓は同一面密度の一重ガラス窓と比べて遮音性能が高い。 | K5: ④ 壁に音が斜め入射する場合，壁の屈曲波の周波数と一致すると，壁が大きく振動して音が透過する。これをコインシデンス効果といい，壁厚が厚い場合は，その効果の対象となる周波数が中低音域まで下がるので，対策を要する場合がある。 | L5: ⑤ 二重壁では，低周波部分で透過損失の著しい落ち込みが見られ，この現象を低音域共鳴透過と呼ぶ。 | M5: 音環境
A6: R2-05 | B6: Ⅲ-5 | C6: 建築環境・設備・建築物衛生管理 | D6: 熱・湿気 | E6: 1 | F6: 夏型結露、北側非暖房室への水蒸気拡散、内部結露・表面結露の発生防止対策に関する正誤判定 | G6: 建物の結露に関する次の記述のうち，最も不適切なものはどれか。 | H6: ① 夏型結露とは，高温多湿の空気が低温度の空間に流れ込んで，相対湿度を上昇させることにより，発生する結露であるため，換気を十分にとることが望ましい。 | I6: ② 家族が集う南側居室から暖房を行っていない北側居室へ水蒸気が拡散した場合，温度が低い外壁内表面や空気流動が少ない押入の中や壁に密着した家具の裏面等に結露が生じる恐れが多い。 | J6: ③ 内部結露の防止には，壁体内に水蒸気が侵入しないようにすることが第一であり，壁体内に防湿層を入れる場合には，温度の高い断熱材の室内側に配置しなければならない。 | K6: ④ 内部結露の防止には，壁体内部の水蒸気を外気に逃がすための通気層を断熱層外側に設ける構法を採用するとよい。 | L6: ⑤ 表面結露の防止には，「室内における水蒸気発生の抑制」，「換気による室内絶対湿度の低下」，「外断熱強化による室内側表面温度の上昇」，「非暖房室などへの水蒸気侵入の抑制」などが考えられる。 | M6: 結露・湿気・湿り空気
A7: R2-06 | B7: Ⅲ-6 | C7: 建築環境・設備・建築物衛生管理 | D7: 換気・室内空気 | E7: 5 | F7: 定常状態における汚染物質濃度式、環境衛生基準数値（CO2, ホルムアルデヒド, CO）および必要換気量基準に関する正誤判定 | G7: 室内の空気汚染に関する次の記述のうち，最も不適切なものはどれか。 | H7: ① 汚染物質が瞬時に一様に拡散する場合の定常状態における室内空気汚染物質気中濃度は，その部屋の汚染物質の発生量，換気量及び外気に含まれる汚染物質濃度によって決まり，部屋の容積には関係しない。 | I7: ② 二酸化炭素濃度基準は，建築物環境衛生管理基準では，1,000ppm以下である。 | J7: ③ シックハウス症候群を防止することを目的に，その原因とされる化学物質について，厚生労働省が定めたホルムアルデヒド室内濃度指針値は，100 μg／m³である。 | K7: ④ 一酸化炭素濃度基準は，建築物環境衛生管理基準では，10ppmを許容濃度としており，不完全燃焼に伴って発生することがあるため，中毒事故防止のために室内酸素濃度を下げないことが大切である。 | L7: ⑤ 居室の必要換気量は，一般に室内の酸素濃度を基準にして決められる。 | M7: 室内空気質・健康影響・衛生動物
A8: R2-07 | B8: Ⅲ-7 | C8: 建築環境・設備・建築物衛生管理 | D8: 空調 | E8: 4 | F8: BEMS、コージェネレーション、全熱交換器外気負荷軽減およびエアフローウィンドウ方式に関する正誤判定 | G8: 省エネルギーシステムに関する次の記述のうち，最も不適切なものはどれか。 | H8: ① BEMSとは室内環境とエネルギー性能の最適化を図るためのビル管理システムである。 | I8: ② コージェネレーション方式を採用する際，熱エネルギー消費量と電力消費量のバランスを年間を通じて図る必要がある。 | J8: ③ 全熱交換器を用いて換気を行う場合，外気負荷は全熱交換器の熱回収効率に応じて軽減することができる。 | K8: ④ 事務所の場合，給気のCO2濃度をもとに取入れ外気量を制御することで外気負荷の軽減を図れる。 | L8: ⑤ エアフローウィンドウ方式は，ペリメーターゾーン専用の空調系統が不要で，混合損失がないため，省エネルギー性能が高い。 | M8: 空調方式・省エネルギー
A9: R2-08 | B9: Ⅲ-8 | C9: 建築環境・設備・建築物衛生管理 | D9: 空調 | E9: 2 | F9: 冷房時におけるすきま換気量、温湿度差に基づく顕熱負荷・潜熱負荷計算 | G9: 以下の条件で冷房している室のすきま換気による顕熱負荷，潜熱負荷に最も近い組合せはどれか。 空気密度：1.2 kg/m³，空気定圧比熱：1,000 J/kg・K すきま換気量：36.0 m³/h，水の蒸発熱：2,500 J/g 外気温度：34.3 ℃，外気絶対湿度：0.022 kg/kg(DA) 室内空気温度：26.0 ℃，室内絶対湿度：0.012 kg/kg(DA) | H9: ① 83W / 250W | I9: ② 100W / 300W | J9: ③ 312W / 360W | K9: ④ 412W / 660W | L9: ⑤ 359kW / 1,080kW | M9: 空調計算（負荷・空気線図・冷凍サイクル）
A10: R2-09 | B10: Ⅲ-9 | C10: 建築環境・設備・建築物衛生管理 | D10: 空調 | E10: 5 | F10: 冷却式・吸着式・圧縮式・吸収式除湿装置の特徴と原理比較に関する正誤判定 | G10: 除湿装置に関する次の記述のうち，最も不適切なものはどれか。 | H10: ① 冷却式除湿装置は，機構が簡単で，設備費が安く，空気の露点温度が高い場合に有利である。 | I10: ② 吸着式除湿装置は，水分を吸着する性質をもつシリカゲル，活性アルミナ，合成ゼオライト，活性炭などの吸着剤を利用したものである。 | J10: ③ 圧縮式除湿装置は，空気を圧縮することによって水蒸気の分圧を増加させ，水蒸気の飽和点を超えさせて凝縮分離する方式であり，設備費及び運転費が高くなる。 | K10: ④ 冷却式除湿装置は，処理空気の温度低下と相対湿度の上昇を伴うため，これらが問題となる場合は，冷却除湿後の空気を加熱（再熱）する必要がある。 | L10: ⑤ 吸収式除湿装置は，大がかりな装置になるが，制御しやすいため幅広く使用されている。 | M10: 空調機器・ダクト・熱源
A11: R2-10 | B11: Ⅲ-10 | C11: 建築環境・設備・建築物衛生管理 | D11: 空調 | E11: 2 | F11: 床吹出し空調、ファンコイルユニット、天井放射空調、パッケージ空調および単ダクトVAV方式の比較と正誤判定 | G11: 空調方式に関する次の記述のうち，最も不適切なものはどれか。 | H11: ① 床吹出し空調方式は，床吹出し口の移設・増設を比較的容易に行えるため，パーソナル性に優れている。 | I11: ② ファンコイルユニットは，一般的に除湿と加湿能力を有し，温度と湿度の個別制御性に優れている。 | J11: ③ 天井放射空調方式は，外調システムと組合せて利用される場合が多い。 | K11: ④ パッケージ空調方式は，外気負荷削減のために全熱交換ユニットなどの機器と組合せて用いられる場合が多い。 | L11: ⑤ 単ダクト変風量空調方式は，原則として給気温湿度を一定として，分岐ダクトに設置したVAVユニットにより風量が各々調整される。 | M11: 空調方式・省エネルギー
A12: R2-11 | B12: Ⅲ-11 | C12: 建築環境・設備・建築物衛生管理 | D12: 給排水・防災 | E12: 3 | F12: 通気管の最小管径（30mm/50mm）、伸頂通気管径、排水立管径および地中埋設管径の技術基準に関する正誤判定 | G12: 給排水に関する次の記述のうち，最も不適切なものはどれか。 | H12: ① 通気管の最小管径は30mmとする。ただし，排水槽に設ける通気管の最小管径は50mmとする。 | I12: ② 伸頂通気管の管径を排水立て管の管径よりも小さくしてはならない。 | J12: ③ 排水立て管は，管の上下方向で負担する排水負荷を考慮し，下階ほど管径を大きくする。 | K12: ④ 地中埋設の排水管の管径は50mm以上とすることが望ましい。 | L12: ⑤ 排水管は，立て管・横管いずれの場合でも，排水の流下方向で管径を縮小してはならない。 | M12: 排水・通気・衛生器具
A13: R2-12 | B13: Ⅲ-12 | C13: 建築環境・設備・建築物衛生管理 | D13: 給排水・防災 | E13: 4 | F13: 排煙設備の法根拠、火災時の煙の2層流動、竪穴区画・避難区画の目的および加圧防煙方式の正誤判定 | G13: 排煙設備に関する次の記述のうち，最も不適切なものはどれか。 | H13: ① 排煙設備の設置義務と技術基準は，建築基準法及び消防法に定められている。 | I13: ② 火災が拡大して火災室より廊下へ流出した煙は，煙と空気の2層を形成しながら流動する。 | J13: ③ 竪穴区画は，煙の侵入を防止することが重要であり，排煙する設備は設けない。 | K13: ④ 避難区画は，居室・廊下・階段の間に間仕切りを設け，在室者がより安全度の高い所に避難できるようにするための区画である。 | L13: ⑤ 加圧防煙方式とは，避難計画上の重要な空間に新鮮空気を供給して内圧を高め，煙の侵入を防ぐ方式である。 | M13: 防災・排煙・消火
... A36: R2-35 | B36: Ⅲ-35 | C36: 廃棄物管理 | D36: 災害廃棄物・事業方式・統計・管理票 | E36: 2 | F36: 大規模災害発生時の二次仮置場運搬、コンクリートくず処理柔軟性、選別方針、行動指針目的および市町村固有事務位置付けの正誤判定 | G36: 「大規模災害発生時における災害廃棄物対策行動指針（平成27年11月 環境省大臣官房廃棄物・リサイクル対策部）」に関する次の記述のうち，最も不適切なものはどれか。 | H36: ① 大規模災害発生時に道路際や空地等に集積された廃棄物は，可能な限り分別した上で速やかに一次仮置場へ運搬，撤去する。 | I36: ② 災害廃棄物の処理期間は，地域及び災害廃棄物の特性に応じて柔軟に設定すべきものであるが，特にコンクリートくずは早期に処理すべきものである。 | J36: ③ 災害廃棄物の選別に当たっては，後工程となる焼却処理や再生利用を効率的に行う観点から処理方針を検討する。 | K36: ④ この指針は，大規模災害発生時においても災害廃棄物を適正かつ円滑・迅速に処理するための基本的考え方，対応方針を整理するものである。 | L36: ⑤ 災害廃棄物の処理は市町村が行う固有事務として位置付けられている。 | M36: 災害廃棄物・指定廃棄物

Sheet R1再(令和元年再試験)問題・選択肢
A1: 問題ID | B1: 設問番号 | C1: 大分類(ブロック) | D1: サブジャンル | E1: 公式正答 | F1: 問題のテーマ・内容概要 | G1: 問題文 | H1: 選択肢① | I1: 選択肢② | J1: 選択肢③ | K1: 選択肢④ | L1: 選択肢⑤ | M1: 出題論点（細目）
A2: R1再-01 | B2: Ⅲ-1 | C2: 建築環境・設備・建築物衛生管理 | D2: 光・音 | E2: 4 | F2: 照明方式、照度計算、ランプ効率および演色評価数に関する正誤判定 | G2: 照明に関する次の記述のうち，最も不適切なものはどれか。 | H2: ① 出射する光束の密度を光束発散度[rlx]という。 | I2: ② 光束は，単位時間当たりの光の放射エネルギーに，波長ごとの人間の視覚の感度である標準比視感度を乗じて求めた値である。 | J2: ③ 窓や照明器具など光源からの直接光による直接照度と，壁や家具での反射を経た間接光による間接照度をそれぞれ計算し，両者の和を全照度とする計算方法を逐点法という。 | K2: ④ メタルハライドランプのランプ効率[lm/W]は，ハロゲンランプのランプ効率[lm/W]よりも低い。 | L2: ⑤ 平均演色評価数Raは，15試験色のうち1から8番目の試験色に関する特殊演色評価数の平均値で表される。 | M2: 照明・光環境
A3: R1再-02 | B3: Ⅲ-2 | C3: 建築環境・設備・建築物衛生管理 | D3: 光・音 | E3: 2 | F3: 光の性質、マンセル表色系、加法混色および演色性に関する正誤判定 | G3: 光・色彩に関する次の記述のうち，最も不適切なものはどれか。 | H3: ① 長年紫外線を浴び続けた結果，高齢者の水晶体は特に500nm以下の短波長である青色光領域の透過率の低下が著しくなる。 | I3: ② 加法混色の三原色は，青緑，赤紫，黄である。 | J3: ③ JISに採用されているマンセル表色系は，ヒュー（Hue），バリュー（Value），クロマ（Chroma）の3属性で表される。 | K3: ④ 色票を用いた視感による測色は，光源に対する注意や面積効果を排除するなどの配慮が必要である。 | L3: ⑤ 赤と緑のように色相が相反していても，明度が同程度に見えにくくなる現象をリープマン効果という。 | M3: 照明・光環境
A4: R1再-03 | B4: Ⅲ-3 | C4: 建築環境・設備・建築物衛生管理 | D4: 熱・湿気 | E4: 1 | F4: 完全黒体放射、熱貫流、熱伝達率および表面放熱特性に関する正誤判定 | G4: 熱移動に関する次の記述のうち，最も不適切なものはどれか。 | H4: ① 完全黒体から放射される熱線のエネルギーは，絶対温度に比例する。 | I4: ② 単層壁の熱貫流は，壁体内部では熱伝導，壁の表面では対流及び放射によって行われている。 | J4: ③ 放射熱伝達率は，固体表面の性質に影響を受ける。 | K4: ④ 床面の対流熱伝達率は，暖房時の方が冷房時よりも小さい。 | L4: ⑤ 壁の対流熱伝達率は，外気側の方が室内側よりも大きい。 | M4: 伝熱・断熱
A5: R1再-04 | B5: Ⅲ-4 | C5: 建築環境・設備・建築物衛生管理 | D5: 換気・室内空気 | E5: 5 | F5: 全般換気、置換換気、必要換気量、給排気口位置および空気齢の定義に関する正誤判定 | G5: 換気に関する次の記述のうち，最も不適切なものはどれか。 | H5: ① 全般換気は，室内全体の空気を稀釈しながら入れ換えるものであり，住宅の居室や事務所ビルの執務室などに多く用いられる。 | I5: ② 置換換気システムは室温より低温の空調空気を気流による不快感が問題とならない低風速で室下部の居住域に直接供給し，室上部で排気するシステムである。 | J5: ③ ある汚染物質が瞬時に一様に拡散とした場合，汚染物質を許容濃度に維持するための必要換気量は汚染物質の発生量と外気濃度で決定され，室容積は関係しない。 | K5: ④ 新鮮外気取入れ口は，道路など建物周辺の状況や排気口の位置も考慮して，清浄な空気が常に確保できるような位置に設け，排気口は，周辺の建物などに支障のない位置に設けなければならない。 | L5: ⑤ 空気齢とは，1つの室に1つずつ吹出し口と排気口がある場合において，空気が吹出し口から排気口に至るまでの時間のことを指す。 | M5: 換気・通風
A6: R1再-05 | B6: Ⅲ-5 | C6: 建築環境・設備・建築物衛生管理 | D6: 光・音 | E6: 3 | F6: 北緯35度の日射・日射調整 | G6: 北緯35度の地点の日射及び日射調整に関する次の記述のうち，最も不適切なものはどれか。 | H6: ① 南鉛直面の終日日射量は日射を遮蔽したい夏至のときに最小となる。 | I6: ② 大気透過率が大きいほど，直達日射が強く，逆に天空日射が弱くなる。 | J6: ③ 北鉛直面は，年間を通じて日照を受けない。 | K6: ④ 東西鉛直面の日射は日の出・日没付近の，太陽高度の低い状況に対応しているので，日射の調整には庇以外のブラインドなどが必要となる。 | L6: ⑤ 冬至の水平面の終日日射量は，夏至の南鉛直面の終日日射量に比較して多い。 | M6: 日照・日射・採光
A7: R1再-06 | B7: Ⅲ-6 | C7: 建築環境・設備・建築物衛生管理 | D7: 光・音 | E7: 4 | F7: 点音源の距離減衰（距離2倍）と音響出力変化（出力2倍）に伴う音圧レベル変化の計算 | G7: 次の図（a）に示すように，音響出力W[W]の点音源から2m離れたA点の音圧レベルが65dBであった。図（b）に示すように，この音源の音響出力が2倍（2W[W]）になった場合，音源から4m離れたB点の音圧レベルに最も近い値は次のうちどれか。 | H7: ① 56dB | I7: ② 57dB | J7: ③ 59dB | K7: ④ 62dB | L7: ⑤ 65dB | M7: 音環境
A8: R1再-07 | B8: Ⅲ-7 | C8: 建築環境・設備・建築物衛生管理 | D8: 温熱・省エネ指標 | E8: 1 | F8: 平均日射熱取得率ηA、UA値、PAL*および一次エネルギー消費量の正誤判定 | G8: 建築物の省エネルギー性能指標に関する次の記述のうち，最も不適切なものはどれか。 | H8: ① 住宅における冷房期の平均日射熱取得率（ηA）は，冷房期の総日射熱取得量を床面積で除して算出される。 | I8: ② 外皮平均熱貫流率（UA）は，室内外の温度差が1℃のときの建物全体の外皮で生じる総熱損失量を外皮（外壁や窓等）の表面積の合計で除して算出される。 | J8: ③ 外皮基準の指標である従来の年間熱負荷係数（PAL）に対し，年間熱負荷係数（PAL*）は潜熱負荷を含めて評価している。 | K8: ④ 非住宅建築物の暖冷房負荷の算出においては，取入外気の熱についても勘案する必要がある。 | L8: ⑤ 一次エネルギーとは，化石燃料，原子力燃料，水力，太陽光など自然から得られるエネルギーのことをいう。 | M8: 省エネ性能指標・都市建築環境
A9: R1再-08 | B9: Ⅲ-8 | C9: 建築環境・設備・建築物衛生管理 | D9: 空調 | E9: 3 | F9: ノズル形、アネモ形、パン形、スロット形吹出口の構造特性と用途比較の正誤判定 | G9: 吹出口及び吸込口に関する次の記述のうち，最も不適切なものはどれか。 | H9: ① ノズル形吹出口は，フェースのまったくない形で劇場などにおいて到達距離をふやすために吹出風速を 5 m/s 以上にして用いることができる。 | I9: ② アネモスタット形吹出口は，吹出口の中で最も大きな誘引性能を有しており，吹出温度差をきわめて大きくとることができる。 | J9: ③ パン形吹出口は，吹出口の方向を左右，上下に変えることができる首振り形のノズル形吹出口の1つで，厨房などのスポット冷房に適している。 | K9: ④ スロット形吹出口は，著しくアスペクト比の大きい吹出口で，体裁がよいので意匠を重視する室に多く使用されている。 | L9: ⑤ 固定羽根型吸込口又はユニバーサル型吸込口は，壁付及び天井付の吸込口として最も多く用いられている。 | M9: 空調機器・ダクト・熱源
A10: R1再-09 | B10: Ⅲ-9 | C10: 建築環境・設備・建築物衛生管理 | D10: 給排水・防災 | E10: 2 | F10: 給湯配管（複管式）、ガス給湯器「号」定義、ポンプ配置、スイベルジョイントおよびベローズ継手の正誤判定 | G10: 給湯設備に関する次の記述のうち，最も不適切なものはどれか。 | H10: ① 給湯栓を開けて即座に湯が必要になるホテルなどでは返湯管を設け，管内の湯を循環させて湯温を一定に保つことで湯待ち時間を小さくする複管式が用いられる。 | I10: ② ガス給湯器では能力表示に「号」を用いるが，1号は流量 1 [L/min] の水の温度を 20℃上昇させる能力である。 | J10: ③ 強制循環方式における循環ポンプは，一般に貯湯槽の直前の返湯管部分に設置する。 | K10: ④ スイベルジョイント工法とは，配管の分岐部に複数のエルボを組合せて用い，可とう性を持たせた配管工法である。 | L10: ⑤ ベローズ型伸縮継手とは，波型の管が伸縮動作を吸収する形式の継手である。 | M10: 給水・給湯
A11: R1再-10 | B11: Ⅲ-10 | C11: 建築環境・設備・建築物衛生管理 | D11: 給排水・防災 | E11: 4 | F11: オフセット配管、伸頂通気管、掃除口間隔、各個通気立ち上げ高さおよびループ通気方式の正誤判定 | G11: 排水・通気配管に関する次の記述のうち，最も不適切なものはどれか。 | H11: ① 建物の最下階にピロティや駐車場があり，そこに排水立て管が通過する際，水平移動して経路を変更する配管部をオフセットという。 | I11: ② 伸頂通気管とは排水立て管の頂部に設置する通気管であり，原則としてその端部を大気に開放する。 | J11: ③ 掃除口は，排水管径が100mm以下の場合は15m以内ごと，100mmを超える場合は30m以内ごとに設置する。 | K11: ④ 各個通気管は，各衛生器具の器具排水管にそれぞれ設置する通気管で，その器具にあふれ縁より50mm以上立ち上げて通気横枝管等に接続する。 | L11: ⑤ ループ通気管を用いるループ通気方式は，排水横枝管に複数接続された衛生器具のトラップを保護する効果的な方法である。 | M11: 排水・通気・衛生器具
A12: R1再-11 | B12: Ⅲ-11 | C12: 建築環境・設備・建築物衛生管理 | D12: 換気・室内空気 | E12: 1 | F12: エアフィルタ・電気集じん器 | G12: 空気調和設備におけるエアフィルタ及び電気集じん器に関する次の記述のうち，最も不適切なものはどれか。 | H12: ① 粉じん保持容量は，エアフィルタの空気抵抗が最初の1.5倍になるまでフィルタ面に捕集されたじんあい量であり，高性能のものほど大きくなる。 | I12: ② エアフィルタの効率の測定方法を大別すると重量法，変色度法及びDOP法の3方法があり，DOP法が最も厳格なテストになる。 | J12: ③ エアフィルタの乾性ろ過式は，ふるいのようにフィルタの目より大きいごみをこして除去するもので，中性能・高性能はほとんどこの方式である。 | K12: ④ エアフィルタの粘性式は，フィルタ中を通る気流がろ材の繊維を避けながらジグザグに進む間にごみがろ材表面（油塗布）に付着し，除去されるものである。 | L12: ⑤ 静電式（電気集じん器）は，ごみを含む空気を放電現場に通してごみに帯電させ，この帯電したごみを陽極板に吸引し，除去するものである。 | M12: 室内空気質・健康影響・衛生動物
A13: R1再-12 | B13: Ⅲ-12 | C13: 建築環境・設備・建築物衛生管理 | D13: 給排水・防災 | E13: 2 | F13: 洗浄弁方式・ロータンク方式給水管径・圧力要件、洗い出し式便器および節水型JIS規格の正誤判定 | G13: 大便器に関する次の記述のうち，最も不適切なものはどれか。 | H13: ① 望ましい大便器の条件としては，乾燥面が少なく留水面が広いこと，排水路内径が大きいことなどが挙げられる。 | I13: ② 洗浄弁方式による給水は，給水管の管径が25mm以上，必要給水圧力が30kPa以上必要である。 | J13: ③ ロータンク式による給水は，給水管の管径が13mm程度，必要給水圧力は一般水栓と同じ30kPaと低くてよい。 | K13: ④ 洗浄方式の分類における洗い出し式は，和風便器に使われ，汚物を一時便器の上にためるので臭気が強いが，安価である。 | L13: ⑤ 節水形大便器の洗浄水量はJIS規格において，節水Ⅰ形でおよそ8.5リットル以下，節水Ⅱ形でおよそ6.5リットル以下と規定されている。 | M13: 排水・通気・衛生器具
... A36: R1再-35 | B36: Ⅲ-35 | C36: 廃棄物管理 | D36: 最終処分場・浸出水 | E36: 5 | F36: オープン型処分場（面積5.0ha、降水量2000mm/年、蒸発散量2.0mm/日）における日平均浸出水量（175m³/日）と浸出係数（0.6）計算 | G36: 最終処分場の浸出水量に関する次の記述の，［ ］に入る数値の組合せとして，最も適切なものはどれか。 「表面遮水工が設置されているオープン型最終処分場において，埋立面積が 5.0ha，年間降水量が 2000mm／年，蒸発散量が 2.0mm／日の場合，日平均浸出水発生量は［ A ］m³／日，浸出係数は［ B ］である。ただし，埋立地に降った雨水が表流水として外部へ排除されることはないものとする。」 | H36: ① A: 100 / B: 0.4 | I36: ② A: 100 / B: 0.6 | J36: ③ A: 140 / B: 0.5 | K36: ④ A: 175 / B: 0.4 | L36: ⑤ A: 175 / B: 0.6 | M36: 最終処分場・浸出水

Sheet R1本(令和元年本試験)問題・選択肢
A1: 問題ID | B1: 設問番号 | C1: 大分類(ブロック) | D1: サブジャンル | E1: 公式正答 | F1: 問題のテーマ・内容概要 | G1: 問題文 | H1: 選択肢① | I1: 選択肢② | J1: 選択肢③ | K1: 選択肢④ | L1: 選択肢⑤ | M1: 出題論点（細目）
A2: R1本-01 | B2: Ⅲ-1 | C2: 建築環境・設備・建築物衛生管理 | D2: 光・音 | E2: 1 | F2: 点光源の水平面照度(200cd,2m,60°) | G2: 下図に示す点光源に照らされたA点の水平面照度に最も近い値はどれか。ただし，点光源の配光特性は一様なものとし，反射は考慮しないものとする。［図：点光源の光度200cd，点光源は床面から高さ2m，A点は点光源の真下から見て鉛直方向60°の位置］ | H2: ① 6.3 lx | I2: ② 8.3 lx | J2: ③ 10.8 lx | K2: ④ 12.5 lx | L2: ⑤ 50.0 lx | M2: 照明・光環境
A3: R1本-02 | B3: Ⅲ-2 | C3: 建築環境・設備・建築物衛生管理 | D3: 温熱・省エネ指標 | E3: 1 | F3: 室内の温度分布 | G3: 室内の温度分布に関する次の記述のうち，最も不適切なものはどれか。 | H3: ① 良好な温熱環境を実現するためには，極端な室内温度分布が生じるのは好ましくないため，床上0.1mから1.1m間の上下温度差分布は5℃以内に抑えるのが好ましい。 | I3: ② 夏期に日射熱が室内へ侵入する場合や外気温が高い場合は，窓側の空気温度は室の奥よりも高くなり，冬期に隙間風が侵入する場合や外気温が低い場合は，窓側の空気温度は低くなる傾向にある。 | J3: ③ 室内には種々の発熱体が存在し，近傍の空気温度を上昇させる。この高温空気は密度が小さいため，浮力により上昇気流を発生させる場合がある。 | K3: ④ 空調・換気設備は，床面より1.8m程度までの居住域を良好な温熱空気環境に保つことが目的であるが，室内に温度分布を生じさせる原因でもある。 | L3: ⑤ エアフローウィンドウは，2枚のガラスの間にブラインドを設けたもので，窓枠下部から室内空気を吸引し，これを窓上部から排気するものである。 | M3: 温熱環境・温熱指標
A4: R1本-03 | B4: Ⅲ-3 | C4: 建築環境・設備・建築物衛生管理 | D4: 熱・湿気 | E4: 2 | F4: 材料の熱定数 | G4: 材料の熱定数に関する次の記述のうち，最も不適切なものはどれか。 | H4: ① 中空層の熱抵抗は，熱流方向が下向きの方が上向きより大きい。 | I4: ② グラスウールの熱伝導率は，かさ比重が小さいほど小さくなる傾向がある。 | J4: ③ 畳の熱伝導率は，木材と同程度である。 | K4: ④ ALCの熱伝導率は，普通コンクリートの1／10程度である。 | L4: ⑤ 二重ガラスなど密閉中空層の熱抵抗は，壁の中空層など半密閉中空層の2倍程度である。 | M4: 伝熱・断熱
A5: R1本-04 | B5: Ⅲ-4 | C5: 建築環境・設備・建築物衛生管理 | D5: 光・音 | E5: 1 | F5: 日照・日射 | G5: 日照・日射に関する次の記述のうち，最も不適切なものはどれか。 | H5: ① 実効放射量（夜間放射量）は，雲があるときは，雲がないときに比較して増加する。 | I5: ② 東西に長い集合住宅において，東京で日照時間を4時間確保するための隣棟間隔係数（隣棟間隔d／建物高さh）は，2程度となる。 | J5: ③ 熱線吸収ガラスは，冷房時に効果がある。 | K5: ④ 対向建物などがない場合は，ガラスのない開放された窓では，近似的に直接昼光率と立体角投射率［%］は一致する。 | L5: ⑤ 頂側窓は，昼光によって展示品を鑑賞したい美術館の展示室や面積の大きい工場に用いられる。 | M5: 日照・日射・採光
A6: R1本-05 | B6: Ⅲ-5 | C6: 建築環境・設備・建築物衛生管理 | D6: 光・音 | E6: 3 | F6: 音環境 | G6: 音環境に関する次の記述のうち，最も不適切なものはどれか。 | H6: ① 障壁は，回折による高音域の遮断に対する効果が大きい。 | I6: ② 音響エネルギー密度が60dBだけ減衰するのに要する時間を残響時間という。 | J6: ③ 多孔質材の吸音機構において，剛壁に直貼りしたときの吸音率は，吸音材の材厚を厚くしても，低音域の吸音率は向上しない。 | K6: ④ 重量衝撃音の低減に対しては，床構造の曲げ剛性や質量が重要で，木造などの軽量床の場合，必要な性能を得ることは困難である。 | L6: ⑤ コインシデンス効果は，音がさまざまな方向から壁面に入射する場合には広い周波数で発生する。 | M6: 音環境
A7: R1本-06 | B7: Ⅲ-6 | C7: 建築環境・設備・建築物衛生管理 | D7: 換気・室内空気 | E7: 4 | F7: 自然換気 | G7: 自然換気に関する次の記述のうち，最も不適切なものはどれか。 | H7: ① 窓を開放した場合などの開口部通過風量は，開口部面積に比例し，圧力差の平方根に比例する。 | I7: ② 実効面積αAにおけるαは流量係数であり，開口の形状や寸法で異なるが，通常端部が直角に整形された窓では0.6～0.7程度となる。 | J7: ③ 中性帯の位置は，定性的には開口部の大きい方に近づく。 | K7: ④ 2つの開口部があるとき，2つの開口部とも負の風圧係数となる場合，それらの風圧係数に差があっても風力換気は生じない。 | L7: ⑤ 高さの異なる2つの開口部があるときの温度差換気量は，直列合成した実効面積αAに比例するとともに，室内外温度差及び開口高さの差の平方根に比例して増加する。 | M7: 換気・通風
A8: R1本-07 | B8: Ⅲ-7 | C8: 建築環境・設備・建築物衛生管理 | D8: 給排水・防災 | E8: 3 | F8: 水配管 | G8: 水配管に関する次の記述のうち，最も不適切なものはどれか。 | H8: ① 開放式は必ず摩擦抵抗のほかに押し上げ揚程が加わり，密閉式に比べてポンプ動力が大きくなる。 | I8: ② 二方弁制御は三方弁制御に比べて一般に制御性が良く，ポンプの台数制御などによりポンプの消費電力を節約できる。 | J8: ③ 満水状態で流体が流れる場合の直管部摩擦抵抗は，管の長さと流体の密度及び流速の2乗に比例し，管の内径と管摩擦係数に反比例する。 | K8: ④ リバースリターン方式では，各機器を通る配管長さが等しく，抵抗が同じとなるために，流量が自然に均一になるという特徴がある。 | L8: ⑤ 普通の屋内配管では，浸食を防ぐための管内流速を一般に2.0m／s以下としている。 | M8: 給水・給湯
A9: R1本-08 | B9: Ⅲ-8 | C9: 建築環境・設備・建築物衛生管理 | D9: 空調 | E9: 5 | F9: 省エネ設備機器 | G9: 省エネルギー設備機器に関する次の記述のうち，最も不適切なものはどれか。 | H9: ① 空気調和機に使用する全熱交換器では，外気冷房が可能なときに給排気バイパスなどにより熱交換を回避する。 | I9: ② 夜間電力利用の蓄熱槽システムでは，熱源の夜間運転時間が長いほど，熱源容量は小さくて済む。 | J9: ③ コージェネレーションシステムは，ガスタービンやガスエンジン，燃料電池などを用いて電力エネルギーと熱エネルギーの両者を同時に供給するシステムであり，総合効率は最大80%程度まで期待することができる。 | K9: ④ 多結晶シリコン太陽電池は，単結晶シリコン太陽電池と比較して変換効率が低いが，製造が容易で効率とコストのバランスが良いため，よく普及している太陽電池である。 | L9: ⑤ ヒートポンプの冷房時の成績係数（COP）は，圧縮仕事に対する凝縮熱量の比で表す。 | M9: 空調方式・省エネルギー
A10: R1本-09 | B10: Ⅲ-9 | C10: 建築環境・設備・建築物衛生管理 | D10: 給排水・防災 | E10: 1 | F10: 給水設備 | G10: 給水設備に関する次の記述のうち，最も不適切なものはどれか。 | H10: ① 高置水槽容量は，揚水ポンプの能力との関係によっても異なるが，一般に1日の使用水量の1／3程度とすることが多い。 | I10: ② 受水槽の有効容量は，水道事業者が断水を考慮して指定要綱などで設計用給水量の4／10～6／10程度の容量を確保するところが多く，概算で1日の使用水量の1／2程度としている。 | J10: ③ 貯水槽はすべての面から点検できるように水槽の上面に1.0m以上，側面と下面に0.6m以上の空間を確保して設置する。 | K10: ④ 井戸を使っている住宅などで，井戸水の配管と水道配管を接続させることはクロスコネクションとなる。 | L10: ⑤ 一般に給水管の給水圧力の上限値は，ホテル・集合住宅で300～400kPa程度，事務所・工場では400～500kPa程度として計画する。 | M10: 給水・給湯
A11: R1本-10 | B11: Ⅲ-10 | C11: 建築環境・設備・建築物衛生管理 | D11: 空調 | E11: 5 | F11: ポンプ及びファン | G11: ポンプ及びファンに関する次の記述のうち，最も不適切なものはどれか。 | H11: ① ラインポンプは小規模な冷温水循環用として配管途中に直接取り付けられるものである。 | I11: ② クロスフローファンはエアコン，ファンコイルユニット，室内空気のサーキュレータなど機器組込みの低圧ファンとして利用されている。 | J11: ③ 遠心ポンプの流量と揚程は羽根車の毎分回転数で変化するが，流量は回転数に比例し，揚程は回転数の2乗に比例する。また，軸動力は回転数の3乗に比例する。 | K11: ④ 空調用の送風機は高い省エネルギー性を求める場合，多翼型のシロッコファンよりも効率の高い後曲型のターボファンを使用する例が増えている。 | L11: ⑤ 渦巻きポンプには羽根車の外に流れの乱れを防ぎポンプ効率を改善するための固定案内羽根がある。 | M11: 空調機器・ダクト・熱源
A12: R1本-11 | B12: Ⅲ-11 | C12: 建築環境・設備・建築物衛生管理 | D12: 空調 | E12: 4 | F12: ボイラー | G12: ボイラーに関する次の記述のうち，最も不適切なものはどれか。 | H12: ① ボイラーの容量は，定格出力すなわち最大連続負荷における毎時出力によって表され，蒸気ボイラーの場合は換算蒸発量［kg／h］又は実際蒸発量［kg／h］，温水ボイラーの場合は熱出力［kW］で表すのが通常である。 | I12: ② 真空式温水機は，鋼板製若しくは鋳鉄製のボイラーの大きな蒸気室に熱交換用のコイルをいくつか配置し，ボイラー内部の蒸気で間接的に暖房用水，給湯用水，プールの水などいくつかの系統の温水を1つのボイラーで加熱するものである。 | J12: ③ 貫流式ボイラーは，燃焼室を取り巻く水管を給水が通過する間に，完全に蒸発する比較的小容量の蒸気ボイラーで，構造が簡単で効率も高く，安価なためにビルや工場などで用いられる。 | K12: ④ 鋳鉄製ボイラーは大容量の高圧型ボイラーで，排気ガスによる給水予熱器又は燃焼空気予熱器などを用いるためボイラー効率は高く，大規模ビルや地域冷暖房プラントなどで用いられる。 | L12: ⑤ ボイラーの排気ガスは地方自治体によってSOx，NOx，煤塵量などが規制されており，市街地でのボイラーの燃料は都市ガスを採用することが多い。 | M12: 空調機器・ダクト・熱源
A13: R1本-12 | B13: Ⅲ-12 | C13: 建築環境・設備・建築物衛生管理 | D13: 給排水・防災 | E13: 3 | F13: 消火設備 | G13: 消火設備に関する次の記述のうち，最も不適切なものはどれか。 | H13: ① 火災は，A火災（普通火災），B火災（油火災），C火災（電気火災），D火災（金属火災）に区分される。 | I13: ② 消防の用に供する設備は，消火設備，警報設備，避難設備の3つに分類される。 | J13: ③ 屋内消火栓設備のホース先端における放水圧力は7MPaを超えないように規定されている。 | K13: ④ 屋外消火栓設備は，1階及び2階の床面積の広い建物に設置し，屋外から屋内に向けて放水によって消火する設備であり，1階及び2階の部分に限って有効な消火設備である。 | L13: ⑤ ドレンチャー消火設備は，建物外部の火災に対し外壁，屋根，開口部に水幕をつくって延焼を防ぐための設備である。 | M13: 防災・排煙・消火
... A36: R1本-35 | B36: Ⅲ-35 | C36: 廃棄物管理 | D36: 災害廃棄物・事業方式・統計・管理票 | E36: 5 | F36: 指定廃棄物 | G36: 指定廃棄物に関する次の記述の，［ ］に入る数値の組合せとして，最も適切なものはどれか。 2011年3月に発生した原子力発電所の事故により放射性物質により汚染された廃棄物のうち，［A］ベクレル／kgを超えるものを指定廃棄物とし，国の責任のもと，適切な方法で処理することとなっている。また，福島県内で除染に伴い発生した除染土壌や［B］ベクレル／kgを超える指定廃棄物等を安全に集中的に管理・保管するために中間貯蔵施設の整備が進められている。 | H36: ① A：100 B：8,000 | I36: ② A：100 B：5万 | J36: ③ A：1,000 B：10万 | K36: ④ A：8,000 B：5万 | L36: ⑤ A：8,000 B：10万 | M36: 災害廃棄物・指定廃棄物

Sheet H30(平成30年度)問題・選択肢
A1: 問題ID | B1: 設問番号 | C1: 大分類(ブロック) | D1: サブジャンル | E1: 公式正答 | F1: 問題のテーマ・内容概要 | G1: 問題文 | H1: 選択肢① | I1: 選択肢② | J1: 選択肢③ | K1: 選択肢④ | L1: 選択肢⑤ | M1: 出題論点（細目）
A2: H30-01 | B2: Ⅲ-1 | C2: 建築環境・設備・建築物衛生管理 | D2: 光・音 | E2: 1 | F2: 床衝撃音（LH/LL）対策、二重窓の空気層、コインシデンス効果、質量則および遮音等級（D値）に関する正誤判定 | G2: 遮音に関する次の記述のうち，最も不適切なものはどれか。 | H2: ① 床の重量衝撃音に対する対策は，床仕上げ材であるカーペットや畳などの緩衝性の材料が効果的である。 | I2: ② 透明ガラスを2重〜3重にはめ殺しにした遮音窓は，できるだけ空気層を厚くとり，その吸音特性を空気層の共鳴周波数に同調させるとよい。 | J2: ③ コインシデンス効果を生じる周波数は，入射波の角度が90°のときに最小となる。 | K2: ④ 壁体の面密度が2倍あるいは周波数が2倍になるごとに，透過損失は6dB増加する。 | L2: ⑤ JIS A1419-1に定める遮音等級において，D-55はD-40よりも遮音性能が高い。 | M2: 音環境
A3: H30-02 | B3: Ⅲ-2 | C3: 建築環境・設備・建築物衛生管理 | D3: 光・音 | E3: 1 | F3: 直射日光と曇天光の色温度、昼光率の安定性、高圧水銀ランプ効率および作業面照度基準の正誤判定 | G3: 採光・照明に関する次の記述のうち，最も不適切なものはどれか。 | H3: ① 直射日光の色温度より，曇天光の色温度の方が低い。 | I3: ② 昼光率は，正確には天空輝度分布の形によって異なるが，屋外の昼光の変動に関わらず，ほぼ一定と考えてよい。 | J3: ③ 蛍光高圧水銀ランプは，白熱電球よりも一般に効率が高い。 | K3: ④ 750 lx以上の作業面照度を必要とするとき，作業周辺部の照度は500 lxとする。 | L3: ⑤ 出射する光束の，反射面の単位面積当たり，単位立体角当たりの大きさを，輝度という。 | M3: 日照・日射・採光
A4: H30-03 | B4: Ⅲ-3 | C4: 建築環境・設備・建築物衛生管理 | D4: 熱・湿気 | E4: 2 | F4: 熱移動 | G4: 熱移動に関する次の記述のうち，最も不適切なものはどれか。 | H4: ① 壁の熱貫流は，壁内部では熱伝導，壁の表面では対流及び放射によって行われている。 | I4: ② 完全黒体から放射される熱線のエネルギーは，絶対温度に比例する。 | J4: ③ 放射熱伝達率は，物体表面が艶消しで真っ黒いほど大きくなる。 | K4: ④ 床面の対流熱伝達率は，暖房時の方が冷房時よりも小さい。 | L4: ⑤ 壁の対流熱伝達率は，外気側の方が室内側よりも大きい。 | M4: 伝熱・断熱
A5: H30-04 | B5: Ⅲ-4 | C5: 建築環境・設備・建築物衛生管理 | D5: 熱・湿気 | E5: 3 | F5: 複層壁体における断熱材（材料2）厚み変更に伴う熱貫流抵抗の倍率計算 | G5: 下図に示すように材料1，材料2から構成される壁体がある。材料2の厚みを2倍にしたとき，壁体の熱貫流抵抗の変更前に対する変更後の比として，最も近い値はどれか。ただし，計算条件は以下のとおりである。 外気側表面熱伝達抵抗 Ro ＝ 0.04 [m²・K/W] 室内側表面熱伝達抵抗 Ri ＝ 0.11 [m²・K/W] 材料1の熱伝導率 λ1 ＝ 1.5 [W/(m・K)]，厚さ 150 mm 材料2の熱伝導率 λ2 ＝ 0.03 [W/(m・K)]，厚さ 30 mm | H5: ① 0.6 | I5: ② 1.0 | J5: ③ 1.8 | K5: ④ 1.9 | L5: ⑤ 2.0 | M5: 伝熱・断熱
A6: H30-05 | B6: Ⅲ-5 | C6: 建築環境・設備・建築物衛生管理 | D6: 熱・湿気 | E6: 1 | F6: 相対湿度・乾球温度・湿球温度・露点温度の関係、水蒸気圧および空気の全圧（ドルトンの法則）に関する正誤判定 | G6: 湿り空気に関する次の記述のうち，最も不適切なものはどれか。 | H6: ① 空気中の相対湿度が50%のとき，湿球温度は乾球温度と同じ値になる。 | I6: ② 水蒸気の多く含まれている空気ほど，露点温度は高くなる。 | J6: ③ 相対湿度は温度変化の影響を受けるが，絶対湿度は温度変化の影響を受けない。 | K6: ④ 一定時間に水面から飛び出す水蒸気分子の数と，湿り空気から水面に飛び込む水蒸気分子の数が同数になるとき，これを平衡状態という。 | L6: ⑤ 乾き空気の分圧と水蒸気分圧を加算したものが湿り空気の全圧となる。 | M6: 結露・湿気・湿り空気
A7: H30-06 | B7: Ⅲ-6 | C7: 建築環境・設備・建築物衛生管理 | D7: 温熱・省エネ指標 | E7: 2 | F7: 温熱快適性(エネルギー代謝・PMV・作用温度) | G7: 温熱快適性に関する次の記述のうち，最も不適切なものはどれか。 | H7: ① 人体のエネルギー代謝は，身体の表面積に比例する。 | I7: ② 人体からの放熱量は，室内温度が上がるにつれて顕熱分の割合が増加する。 | J7: ③ 予測平均温冷感申告の値が −0.5 の場合，予測不満足者率は10%となる。 | K7: ④ 標準新有効温度は，椅座静位状態を前提とした温熱感評価指標である。 | L7: ⑤ 作用温度は静穏気流下ではほぼ空気温度と平均放射温度の相加平均となる。 | M7: 温熱環境・温熱指標
A8: H30-07 | B8: Ⅲ-7 | C8: 建築環境・設備・建築物衛生管理 | D8: 空調 | E8: 5 | F8: 比エンタルピー算出式を用いた乾き空気1,000kg(DA)の蒸気加熱加湿に伴う獲得熱量計算 | G8: 湿り空気の比エンタルピーhは次の式で表せる。 h ＝ 1.0 t ＋ (2500 ＋ 1.8 t) x [kJ/kg(DA)] ただし，t : 乾球温度 [℃]，x : 絶対湿度 [kg/kg(DA)]，kg(DA) : 乾き空気の質量 乾き空気1000 kg(DA)を含む，乾球温度7 ℃，絶対湿度0.004 kg/kg(DA)の湿り空気を，蒸気で加熱・加湿し，乾球温度42 ℃，絶対湿度0.014 kg/kg(DA)としたときの空気の得た熱量として，最も近い値はどれか。 | H8: ① 26 kJ | I8: ② 35 kJ | J8: ③ 61 kJ | K8: ④ 26 MJ | L8: ⑤ 61 MJ | M8: 空調計算（負荷・空気線図・冷凍サイクル）
A9: H30-08 | B9: Ⅲ-8 | C9: 建築環境・設備・建築物衛生管理 | D9: 空調 | E9: 4 | F9: 各種冷凍機（電動・水冷/空冷、吸収式、ターボ、レシプロ）の原理、特徴および構造に関する正誤判定 | G9: 熱源装置に関する次の記述のうち，最も不適切なものはどれか。 | H9: ① 各種電動冷凍機の定格時成績係数は，水冷式の方が空冷式よりも大きい。 | I9: ② 吸収冷凍機では一般に冷媒として水，吸収剤として臭化リチウム溶液が用いられている。 | J9: ③ 遠心冷凍機はターボ冷凍機とも呼ばれ，羽根車の回転による遠心力で冷媒を圧縮するもので，空調用としては大容量の場合に多く用いられている。 | K9: ④ レシプロ冷凍機は回転型圧縮機の一種で，中・大容量のヒートポンプなどに多く用いられている。 | L9: ⑤ 吸収式冷凍の特徴は圧縮機能に比べて電力消費量が少なく，騒音・振動も小さいことである。しかし，形状や重量は大きく，冷却塔の容量も大きくなる。 | M9: 空調機器・ダクト・熱源
A10: H30-09 | B10: Ⅲ-9 | C10: 建築環境・設備・建築物衛生管理 | D10: 換気・室内空気 | E10: 2 | F10: 風力換気力、平均空気齢・平均滞留時間の定義、建築基準法換気基準（20m3/h・人）、CO2発生量および第一種〜第三種換気分類に関する正誤判定 | G10: 換気に関する次の記述のうち，最も不適切なものはどれか。 | H10: ① 風による換気力は，空気自体の持つ運動エネルギーに建物の形状により決まる風圧係数を乗じて求めることができる。 | I10: ② 平均空気齢とは，空気が吹出口から排気口に至るまでの平均時間である。 | J10: ③ 建築物における衛生的な環境の確保に関する法律が適用されない建物での在室人員に必要な新鮮空気を導入する換気は，建築基準法に規定される20 [m³/(h・人)] が一般的に用いられる。 | K10: ④ 人体からのCO₂発生量は安静時で0.013 [m³/(h・人)] 程度，事務作業時で0.02 [m³/(h・人)] 程度である。 | L10: ⑤ 第三種換気とは自然給気と機械排気による換気であり，直接的に外気を自然給気する場合を第三種換気の甲種，間接的に外気を自然給気する場合を第三種換気の乙種と分類する。 | M10: 換気・通風
A11: H30-10 | B11: Ⅲ-10 | C11: 建築環境・設備・建築物衛生管理 | D11: 給排水・防災 | E11: 2 | F11: 受水槽有効容量（1/2日分）、高置水槽容量（1/10日分）、点検空間寸法（上1m/周0.6m）、クロスコネクションおよび適正給水圧力の正誤判定 | G11: 給水設備に関する次の記述のうち，最も不適切なものはどれか。 | H11: ① 受水槽の有効容量は，水道事業者が断水時を考慮して指定要綱などで設計用給水量の 4/10〜6/10 程度の容量を確保するところが多く，概算で1日の使用水量の 1/2 程度としている。 | I11: ② 高置水槽容量は，揚水ポンプの能力との関係によっても異なるが，一般に1日の使用水量の 1/3 程度とすることが多い。 | J11: ③ 貯水槽はすべての面から点検できるように水槽の上面に1.0m以上，側面と下面に0.6m以上の空間を確保して設置する。 | K11: ④ 井戸を使っている住宅などで，井戸水の配管と水道配管を接続させることはクロスコネクションとなる。 | L11: ⑤ 一般に給水管の給水圧力の上限値は，ホテル・集合住宅で300〜400 kPa程度，事務所・工場では400〜500 kPa程度として計画する。 | M11: 給水・給湯
